# NDT Command Reference

*This document is autogenerated by [https://github.com/NitorCreations/nameless-deploy-tools/blob/master/document_commands.py](document_commands.py). Do not edit by hand!*

## `ndt account-id`

```bash
Traceback (most recent call last):
  File "/home/pasi/.pyenv/versions/3.7.2/bin/ndt", line 11, in <module>
    load_entry_point(\'nameless-deploy-tools\', \'console_scripts\', \'ndt\')()
  File "/home/pasi/.pyenv/versions/3.7.2/lib/python3.7/site-packages/pkg_resources/__init__.py", line 484, in load_entry_point
    return get_distribution(dist).load_entry_point(group, name)
  File "/home/pasi/.pyenv/versions/3.7.2/lib/python3.7/site-packages/pkg_resources/__init__.py", line 2714, in load_entry_point
    return ep.load()
  File "/home/pasi/.pyenv/versions/3.7.2/lib/python3.7/site-packages/pkg_resources/__init__.py", line 2332, in load
    return self.resolve()
  File "/home/pasi/.pyenv/versions/3.7.2/lib/python3.7/site-packages/pkg_resources/__init__.py", line 2338, in resolve
    module = __import__(self.module_name, fromlist=[\'__name__\'], level=0)
ImportError: bad magic number in \'n_utils\': b\'\x03\xf3\r\n\'
```

## `ndt add-deployer-server`

```bash
Traceback (most recent call last):
  File "/home/pasi/.pyenv/versions/3.7.2/bin/ndt", line 11, in <module>
    load_entry_point(\'nameless-deploy-tools\', \'console_scripts\', \'ndt\')()
  File "/home/pasi/.pyenv/versions/3.7.2/lib/python3.7/site-packages/pkg_resources/__init__.py", line 484, in load_entry_point
    return get_distribution(dist).load_entry_point(group, name)
  File "/home/pasi/.pyenv/versions/3.7.2/lib/python3.7/site-packages/pkg_resources/__init__.py", line 2714, in load_entry_point
    return ep.load()
  File "/home/pasi/.pyenv/versions/3.7.2/lib/python3.7/site-packages/pkg_resources/__init__.py", line 2332, in load
    return self.resolve()
  File "/home/pasi/.pyenv/versions/3.7.2/lib/python3.7/site-packages/pkg_resources/__init__.py", line 2338, in resolve
    module = __import__(self.module_name, fromlist=[\'__name__\'], level=0)
ImportError: bad magic number in \'n_utils\': b\'\x03\xf3\r\n\'
```

## `ndt assume-role`

```bash
Traceback (most recent call last):
  File "/home/pasi/.pyenv/versions/3.7.2/bin/ndt", line 11, in <module>
    load_entry_point(\'nameless-deploy-tools\', \'console_scripts\', \'ndt\')()
  File "/home/pasi/.pyenv/versions/3.7.2/lib/python3.7/site-packages/pkg_resources/__init__.py", line 484, in load_entry_point
    return get_distribution(dist).load_entry_point(group, name)
  File "/home/pasi/.pyenv/versions/3.7.2/lib/python3.7/site-packages/pkg_resources/__init__.py", line 2714, in load_entry_point
    return ep.load()
  File "/home/pasi/.pyenv/versions/3.7.2/lib/python3.7/site-packages/pkg_resources/__init__.py", line 2332, in load
    return self.resolve()
  File "/home/pasi/.pyenv/versions/3.7.2/lib/python3.7/site-packages/pkg_resources/__init__.py", line 2338, in resolve
    module = __import__(self.module_name, fromlist=[\'__name__\'], level=0)
ImportError: bad magic number in \'n_utils\': b\'\x03\xf3\r\n\'
```

## `ndt assumed-role-name`

```bash
Traceback (most recent call last):
  File "/home/pasi/.pyenv/versions/3.7.2/bin/ndt", line 11, in <module>
    load_entry_point(\'nameless-deploy-tools\', \'console_scripts\', \'ndt\')()
  File "/home/pasi/.pyenv/versions/3.7.2/lib/python3.7/site-packages/pkg_resources/__init__.py", line 484, in load_entry_point
    return get_distribution(dist).load_entry_point(group, name)
  File "/home/pasi/.pyenv/versions/3.7.2/lib/python3.7/site-packages/pkg_resources/__init__.py", line 2714, in load_entry_point
    return ep.load()
  File "/home/pasi/.pyenv/versions/3.7.2/lib/python3.7/site-packages/pkg_resources/__init__.py", line 2332, in load
    return self.resolve()
  File "/home/pasi/.pyenv/versions/3.7.2/lib/python3.7/site-packages/pkg_resources/__init__.py", line 2338, in resolve
    module = __import__(self.module_name, fromlist=[\'__name__\'], level=0)
ImportError: bad magic number in \'n_utils\': b\'\x03\xf3\r\n\'
```

## `ndt bake-docker`

```bash
Traceback (most recent call last):
  File "/home/pasi/.pyenv/versions/3.7.2/bin/ndt", line 11, in <module>
    load_entry_point(\'nameless-deploy-tools\', \'console_scripts\', \'ndt\')()
  File "/home/pasi/.pyenv/versions/3.7.2/lib/python3.7/site-packages/pkg_resources/__init__.py", line 484, in load_entry_point
    return get_distribution(dist).load_entry_point(group, name)
  File "/home/pasi/.pyenv/versions/3.7.2/lib/python3.7/site-packages/pkg_resources/__init__.py", line 2714, in load_entry_point
    return ep.load()
  File "/home/pasi/.pyenv/versions/3.7.2/lib/python3.7/site-packages/pkg_resources/__init__.py", line 2332, in load
    return self.resolve()
  File "/home/pasi/.pyenv/versions/3.7.2/lib/python3.7/site-packages/pkg_resources/__init__.py", line 2338, in resolve
    module = __import__(self.module_name, fromlist=[\'__name__\'], level=0)
ImportError: bad magic number in \'n_utils\': b\'\x03\xf3\r\n\'
```

## `ndt bake-image`

```bash
Traceback (most recent call last):
  File "/home/pasi/.pyenv/versions/3.7.2/bin/ndt", line 11, in <module>
    load_entry_point(\'nameless-deploy-tools\', \'console_scripts\', \'ndt\')()
  File "/home/pasi/.pyenv/versions/3.7.2/lib/python3.7/site-packages/pkg_resources/__init__.py", line 484, in load_entry_point
    return get_distribution(dist).load_entry_point(group, name)
  File "/home/pasi/.pyenv/versions/3.7.2/lib/python3.7/site-packages/pkg_resources/__init__.py", line 2714, in load_entry_point
    return ep.load()
  File "/home/pasi/.pyenv/versions/3.7.2/lib/python3.7/site-packages/pkg_resources/__init__.py", line 2332, in load
    return self.resolve()
  File "/home/pasi/.pyenv/versions/3.7.2/lib/python3.7/site-packages/pkg_resources/__init__.py", line 2338, in resolve
    module = __import__(self.module_name, fromlist=[\'__name__\'], level=0)
ImportError: bad magic number in \'n_utils\': b\'\x03\xf3\r\n\'
```

## `ndt cf-delete-stack`

```bash
Traceback (most recent call last):
  File "/home/pasi/.pyenv/versions/3.7.2/bin/ndt", line 11, in <module>
    load_entry_point(\'nameless-deploy-tools\', \'console_scripts\', \'ndt\')()
  File "/home/pasi/.pyenv/versions/3.7.2/lib/python3.7/site-packages/pkg_resources/__init__.py", line 484, in load_entry_point
    return get_distribution(dist).load_entry_point(group, name)
  File "/home/pasi/.pyenv/versions/3.7.2/lib/python3.7/site-packages/pkg_resources/__init__.py", line 2714, in load_entry_point
    return ep.load()
  File "/home/pasi/.pyenv/versions/3.7.2/lib/python3.7/site-packages/pkg_resources/__init__.py", line 2332, in load
    return self.resolve()
  File "/home/pasi/.pyenv/versions/3.7.2/lib/python3.7/site-packages/pkg_resources/__init__.py", line 2338, in resolve
    module = __import__(self.module_name, fromlist=[\'__name__\'], level=0)
ImportError: bad magic number in \'n_utils\': b\'\x03\xf3\r\n\'
```

## `ndt cf-follow-logs`

```bash
Traceback (most recent call last):
  File "/home/pasi/.pyenv/versions/3.7.2/bin/ndt", line 11, in <module>
    load_entry_point(\'nameless-deploy-tools\', \'console_scripts\', \'ndt\')()
  File "/home/pasi/.pyenv/versions/3.7.2/lib/python3.7/site-packages/pkg_resources/__init__.py", line 484, in load_entry_point
    return get_distribution(dist).load_entry_point(group, name)
  File "/home/pasi/.pyenv/versions/3.7.2/lib/python3.7/site-packages/pkg_resources/__init__.py", line 2714, in load_entry_point
    return ep.load()
  File "/home/pasi/.pyenv/versions/3.7.2/lib/python3.7/site-packages/pkg_resources/__init__.py", line 2332, in load
    return self.resolve()
  File "/home/pasi/.pyenv/versions/3.7.2/lib/python3.7/site-packages/pkg_resources/__init__.py", line 2338, in resolve
    module = __import__(self.module_name, fromlist=[\'__name__\'], level=0)
ImportError: bad magic number in \'n_utils\': b\'\x03\xf3\r\n\'
```

## `ndt cf-get-parameter`

```bash
Traceback (most recent call last):
  File "/home/pasi/.pyenv/versions/3.7.2/bin/ndt", line 11, in <module>
    load_entry_point(\'nameless-deploy-tools\', \'console_scripts\', \'ndt\')()
  File "/home/pasi/.pyenv/versions/3.7.2/lib/python3.7/site-packages/pkg_resources/__init__.py", line 484, in load_entry_point
    return get_distribution(dist).load_entry_point(group, name)
  File "/home/pasi/.pyenv/versions/3.7.2/lib/python3.7/site-packages/pkg_resources/__init__.py", line 2714, in load_entry_point
    return ep.load()
  File "/home/pasi/.pyenv/versions/3.7.2/lib/python3.7/site-packages/pkg_resources/__init__.py", line 2332, in load
    return self.resolve()
  File "/home/pasi/.pyenv/versions/3.7.2/lib/python3.7/site-packages/pkg_resources/__init__.py", line 2338, in resolve
    module = __import__(self.module_name, fromlist=[\'__name__\'], level=0)
ImportError: bad magic number in \'n_utils\': b\'\x03\xf3\r\n\'
```

## `ndt cf-logical-id`

```bash
Traceback (most recent call last):
  File "/home/pasi/.pyenv/versions/3.7.2/bin/ndt", line 11, in <module>
    load_entry_point(\'nameless-deploy-tools\', \'console_scripts\', \'ndt\')()
  File "/home/pasi/.pyenv/versions/3.7.2/lib/python3.7/site-packages/pkg_resources/__init__.py", line 484, in load_entry_point
    return get_distribution(dist).load_entry_point(group, name)
  File "/home/pasi/.pyenv/versions/3.7.2/lib/python3.7/site-packages/pkg_resources/__init__.py", line 2714, in load_entry_point
    return ep.load()
  File "/home/pasi/.pyenv/versions/3.7.2/lib/python3.7/site-packages/pkg_resources/__init__.py", line 2332, in load
    return self.resolve()
  File "/home/pasi/.pyenv/versions/3.7.2/lib/python3.7/site-packages/pkg_resources/__init__.py", line 2338, in resolve
    module = __import__(self.module_name, fromlist=[\'__name__\'], level=0)
ImportError: bad magic number in \'n_utils\': b\'\x03\xf3\r\n\'
```

## `ndt cf-region`

```bash
Traceback (most recent call last):
  File "/home/pasi/.pyenv/versions/3.7.2/bin/ndt", line 11, in <module>
    load_entry_point(\'nameless-deploy-tools\', \'console_scripts\', \'ndt\')()
  File "/home/pasi/.pyenv/versions/3.7.2/lib/python3.7/site-packages/pkg_resources/__init__.py", line 484, in load_entry_point
    return get_distribution(dist).load_entry_point(group, name)
  File "/home/pasi/.pyenv/versions/3.7.2/lib/python3.7/site-packages/pkg_resources/__init__.py", line 2714, in load_entry_point
    return ep.load()
  File "/home/pasi/.pyenv/versions/3.7.2/lib/python3.7/site-packages/pkg_resources/__init__.py", line 2332, in load
    return self.resolve()
  File "/home/pasi/.pyenv/versions/3.7.2/lib/python3.7/site-packages/pkg_resources/__init__.py", line 2338, in resolve
    module = __import__(self.module_name, fromlist=[\'__name__\'], level=0)
ImportError: bad magic number in \'n_utils\': b\'\x03\xf3\r\n\'
```

## `ndt cf-signal-status`

```bash
Traceback (most recent call last):
  File "/home/pasi/.pyenv/versions/3.7.2/bin/ndt", line 11, in <module>
    load_entry_point(\'nameless-deploy-tools\', \'console_scripts\', \'ndt\')()
  File "/home/pasi/.pyenv/versions/3.7.2/lib/python3.7/site-packages/pkg_resources/__init__.py", line 484, in load_entry_point
    return get_distribution(dist).load_entry_point(group, name)
  File "/home/pasi/.pyenv/versions/3.7.2/lib/python3.7/site-packages/pkg_resources/__init__.py", line 2714, in load_entry_point
    return ep.load()
  File "/home/pasi/.pyenv/versions/3.7.2/lib/python3.7/site-packages/pkg_resources/__init__.py", line 2332, in load
    return self.resolve()
  File "/home/pasi/.pyenv/versions/3.7.2/lib/python3.7/site-packages/pkg_resources/__init__.py", line 2338, in resolve
    module = __import__(self.module_name, fromlist=[\'__name__\'], level=0)
ImportError: bad magic number in \'n_utils\': b\'\x03\xf3\r\n\'
```

## `ndt cf-stack-id`

```bash
Traceback (most recent call last):
  File "/home/pasi/.pyenv/versions/3.7.2/bin/ndt", line 11, in <module>
    load_entry_point(\'nameless-deploy-tools\', \'console_scripts\', \'ndt\')()
  File "/home/pasi/.pyenv/versions/3.7.2/lib/python3.7/site-packages/pkg_resources/__init__.py", line 484, in load_entry_point
    return get_distribution(dist).load_entry_point(group, name)
  File "/home/pasi/.pyenv/versions/3.7.2/lib/python3.7/site-packages/pkg_resources/__init__.py", line 2714, in load_entry_point
    return ep.load()
  File "/home/pasi/.pyenv/versions/3.7.2/lib/python3.7/site-packages/pkg_resources/__init__.py", line 2332, in load
    return self.resolve()
  File "/home/pasi/.pyenv/versions/3.7.2/lib/python3.7/site-packages/pkg_resources/__init__.py", line 2338, in resolve
    module = __import__(self.module_name, fromlist=[\'__name__\'], level=0)
ImportError: bad magic number in \'n_utils\': b\'\x03\xf3\r\n\'
```

## `ndt cf-stack-name`

```bash
Traceback (most recent call last):
  File "/home/pasi/.pyenv/versions/3.7.2/bin/ndt", line 11, in <module>
    load_entry_point(\'nameless-deploy-tools\', \'console_scripts\', \'ndt\')()
  File "/home/pasi/.pyenv/versions/3.7.2/lib/python3.7/site-packages/pkg_resources/__init__.py", line 484, in load_entry_point
    return get_distribution(dist).load_entry_point(group, name)
  File "/home/pasi/.pyenv/versions/3.7.2/lib/python3.7/site-packages/pkg_resources/__init__.py", line 2714, in load_entry_point
    return ep.load()
  File "/home/pasi/.pyenv/versions/3.7.2/lib/python3.7/site-packages/pkg_resources/__init__.py", line 2332, in load
    return self.resolve()
  File "/home/pasi/.pyenv/versions/3.7.2/lib/python3.7/site-packages/pkg_resources/__init__.py", line 2338, in resolve
    module = __import__(self.module_name, fromlist=[\'__name__\'], level=0)
ImportError: bad magic number in \'n_utils\': b\'\x03\xf3\r\n\'
```

## `ndt create-account`

```bash
Traceback (most recent call last):
  File "/home/pasi/.pyenv/versions/3.7.2/bin/ndt", line 11, in <module>
    load_entry_point(\'nameless-deploy-tools\', \'console_scripts\', \'ndt\')()
  File "/home/pasi/.pyenv/versions/3.7.2/lib/python3.7/site-packages/pkg_resources/__init__.py", line 484, in load_entry_point
    return get_distribution(dist).load_entry_point(group, name)
  File "/home/pasi/.pyenv/versions/3.7.2/lib/python3.7/site-packages/pkg_resources/__init__.py", line 2714, in load_entry_point
    return ep.load()
  File "/home/pasi/.pyenv/versions/3.7.2/lib/python3.7/site-packages/pkg_resources/__init__.py", line 2332, in load
    return self.resolve()
  File "/home/pasi/.pyenv/versions/3.7.2/lib/python3.7/site-packages/pkg_resources/__init__.py", line 2338, in resolve
    module = __import__(self.module_name, fromlist=[\'__name__\'], level=0)
ImportError: bad magic number in \'n_utils\': b\'\x03\xf3\r\n\'
```

## `ndt create-stack`

```bash
Traceback (most recent call last):
  File "/home/pasi/.pyenv/versions/3.7.2/bin/ndt", line 11, in <module>
    load_entry_point(\'nameless-deploy-tools\', \'console_scripts\', \'ndt\')()
  File "/home/pasi/.pyenv/versions/3.7.2/lib/python3.7/site-packages/pkg_resources/__init__.py", line 484, in load_entry_point
    return get_distribution(dist).load_entry_point(group, name)
  File "/home/pasi/.pyenv/versions/3.7.2/lib/python3.7/site-packages/pkg_resources/__init__.py", line 2714, in load_entry_point
    return ep.load()
  File "/home/pasi/.pyenv/versions/3.7.2/lib/python3.7/site-packages/pkg_resources/__init__.py", line 2332, in load
    return self.resolve()
  File "/home/pasi/.pyenv/versions/3.7.2/lib/python3.7/site-packages/pkg_resources/__init__.py", line 2338, in resolve
    module = __import__(self.module_name, fromlist=[\'__name__\'], level=0)
ImportError: bad magic number in \'n_utils\': b\'\x03\xf3\r\n\'
```

## `ndt deploy-cdk`

```bash
Traceback (most recent call last):
  File "/home/pasi/.pyenv/versions/3.7.2/bin/ndt", line 11, in <module>
    load_entry_point(\'nameless-deploy-tools\', \'console_scripts\', \'ndt\')()
  File "/home/pasi/.pyenv/versions/3.7.2/lib/python3.7/site-packages/pkg_resources/__init__.py", line 484, in load_entry_point
    return get_distribution(dist).load_entry_point(group, name)
  File "/home/pasi/.pyenv/versions/3.7.2/lib/python3.7/site-packages/pkg_resources/__init__.py", line 2714, in load_entry_point
    return ep.load()
  File "/home/pasi/.pyenv/versions/3.7.2/lib/python3.7/site-packages/pkg_resources/__init__.py", line 2332, in load
    return self.resolve()
  File "/home/pasi/.pyenv/versions/3.7.2/lib/python3.7/site-packages/pkg_resources/__init__.py", line 2338, in resolve
    module = __import__(self.module_name, fromlist=[\'__name__\'], level=0)
ImportError: bad magic number in \'n_utils\': b\'\x03\xf3\r\n\'
```

## `ndt deploy-serverless`

```bash
Traceback (most recent call last):
  File "/home/pasi/.pyenv/versions/3.7.2/bin/ndt", line 11, in <module>
    load_entry_point(\'nameless-deploy-tools\', \'console_scripts\', \'ndt\')()
  File "/home/pasi/.pyenv/versions/3.7.2/lib/python3.7/site-packages/pkg_resources/__init__.py", line 484, in load_entry_point
    return get_distribution(dist).load_entry_point(group, name)
  File "/home/pasi/.pyenv/versions/3.7.2/lib/python3.7/site-packages/pkg_resources/__init__.py", line 2714, in load_entry_point
    return ep.load()
  File "/home/pasi/.pyenv/versions/3.7.2/lib/python3.7/site-packages/pkg_resources/__init__.py", line 2332, in load
    return self.resolve()
  File "/home/pasi/.pyenv/versions/3.7.2/lib/python3.7/site-packages/pkg_resources/__init__.py", line 2338, in resolve
    module = __import__(self.module_name, fromlist=[\'__name__\'], level=0)
ImportError: bad magic number in \'n_utils\': b\'\x03\xf3\r\n\'
```

## `ndt deploy-stack`

```bash
Traceback (most recent call last):
  File "/home/pasi/.pyenv/versions/3.7.2/bin/ndt", line 11, in <module>
    load_entry_point(\'nameless-deploy-tools\', \'console_scripts\', \'ndt\')()
  File "/home/pasi/.pyenv/versions/3.7.2/lib/python3.7/site-packages/pkg_resources/__init__.py", line 484, in load_entry_point
    return get_distribution(dist).load_entry_point(group, name)
  File "/home/pasi/.pyenv/versions/3.7.2/lib/python3.7/site-packages/pkg_resources/__init__.py", line 2714, in load_entry_point
    return ep.load()
  File "/home/pasi/.pyenv/versions/3.7.2/lib/python3.7/site-packages/pkg_resources/__init__.py", line 2332, in load
    return self.resolve()
  File "/home/pasi/.pyenv/versions/3.7.2/lib/python3.7/site-packages/pkg_resources/__init__.py", line 2338, in resolve
    module = __import__(self.module_name, fromlist=[\'__name__\'], level=0)
ImportError: bad magic number in \'n_utils\': b\'\x03\xf3\r\n\'
```

## `ndt deploy-terraform`

```bash
Traceback (most recent call last):
  File "/home/pasi/.pyenv/versions/3.7.2/bin/ndt", line 11, in <module>
    load_entry_point(\'nameless-deploy-tools\', \'console_scripts\', \'ndt\')()
  File "/home/pasi/.pyenv/versions/3.7.2/lib/python3.7/site-packages/pkg_resources/__init__.py", line 484, in load_entry_point
    return get_distribution(dist).load_entry_point(group, name)
  File "/home/pasi/.pyenv/versions/3.7.2/lib/python3.7/site-packages/pkg_resources/__init__.py", line 2714, in load_entry_point
    return ep.load()
  File "/home/pasi/.pyenv/versions/3.7.2/lib/python3.7/site-packages/pkg_resources/__init__.py", line 2332, in load
    return self.resolve()
  File "/home/pasi/.pyenv/versions/3.7.2/lib/python3.7/site-packages/pkg_resources/__init__.py", line 2338, in resolve
    module = __import__(self.module_name, fromlist=[\'__name__\'], level=0)
ImportError: bad magic number in \'n_utils\': b\'\x03\xf3\r\n\'
```

## `ndt detach-volume`

```bash
Traceback (most recent call last):
  File "/home/pasi/.pyenv/versions/3.7.2/bin/ndt", line 11, in <module>
    load_entry_point(\'nameless-deploy-tools\', \'console_scripts\', \'ndt\')()
  File "/home/pasi/.pyenv/versions/3.7.2/lib/python3.7/site-packages/pkg_resources/__init__.py", line 484, in load_entry_point
    return get_distribution(dist).load_entry_point(group, name)
  File "/home/pasi/.pyenv/versions/3.7.2/lib/python3.7/site-packages/pkg_resources/__init__.py", line 2714, in load_entry_point
    return ep.load()
  File "/home/pasi/.pyenv/versions/3.7.2/lib/python3.7/site-packages/pkg_resources/__init__.py", line 2332, in load
    return self.resolve()
  File "/home/pasi/.pyenv/versions/3.7.2/lib/python3.7/site-packages/pkg_resources/__init__.py", line 2338, in resolve
    module = __import__(self.module_name, fromlist=[\'__name__\'], level=0)
ImportError: bad magic number in \'n_utils\': b\'\x03\xf3\r\n\'
```

## `ndt ec2-clean-snapshots`

```bash
Traceback (most recent call last):
  File "/home/pasi/.pyenv/versions/3.7.2/bin/ndt", line 11, in <module>
    load_entry_point(\'nameless-deploy-tools\', \'console_scripts\', \'ndt\')()
  File "/home/pasi/.pyenv/versions/3.7.2/lib/python3.7/site-packages/pkg_resources/__init__.py", line 484, in load_entry_point
    return get_distribution(dist).load_entry_point(group, name)
  File "/home/pasi/.pyenv/versions/3.7.2/lib/python3.7/site-packages/pkg_resources/__init__.py", line 2714, in load_entry_point
    return ep.load()
  File "/home/pasi/.pyenv/versions/3.7.2/lib/python3.7/site-packages/pkg_resources/__init__.py", line 2332, in load
    return self.resolve()
  File "/home/pasi/.pyenv/versions/3.7.2/lib/python3.7/site-packages/pkg_resources/__init__.py", line 2338, in resolve
    module = __import__(self.module_name, fromlist=[\'__name__\'], level=0)
ImportError: bad magic number in \'n_utils\': b\'\x03\xf3\r\n\'
```

## `ndt ec2-get-tag`

```bash
Traceback (most recent call last):
  File "/home/pasi/.pyenv/versions/3.7.2/bin/ndt", line 11, in <module>
    load_entry_point(\'nameless-deploy-tools\', \'console_scripts\', \'ndt\')()
  File "/home/pasi/.pyenv/versions/3.7.2/lib/python3.7/site-packages/pkg_resources/__init__.py", line 484, in load_entry_point
    return get_distribution(dist).load_entry_point(group, name)
  File "/home/pasi/.pyenv/versions/3.7.2/lib/python3.7/site-packages/pkg_resources/__init__.py", line 2714, in load_entry_point
    return ep.load()
  File "/home/pasi/.pyenv/versions/3.7.2/lib/python3.7/site-packages/pkg_resources/__init__.py", line 2332, in load
    return self.resolve()
  File "/home/pasi/.pyenv/versions/3.7.2/lib/python3.7/site-packages/pkg_resources/__init__.py", line 2338, in resolve
    module = __import__(self.module_name, fromlist=[\'__name__\'], level=0)
ImportError: bad magic number in \'n_utils\': b\'\x03\xf3\r\n\'
```

## `ndt ec2-get-userdata`

```bash
Traceback (most recent call last):
  File "/home/pasi/.pyenv/versions/3.7.2/bin/ndt", line 11, in <module>
    load_entry_point(\'nameless-deploy-tools\', \'console_scripts\', \'ndt\')()
  File "/home/pasi/.pyenv/versions/3.7.2/lib/python3.7/site-packages/pkg_resources/__init__.py", line 484, in load_entry_point
    return get_distribution(dist).load_entry_point(group, name)
  File "/home/pasi/.pyenv/versions/3.7.2/lib/python3.7/site-packages/pkg_resources/__init__.py", line 2714, in load_entry_point
    return ep.load()
  File "/home/pasi/.pyenv/versions/3.7.2/lib/python3.7/site-packages/pkg_resources/__init__.py", line 2332, in load
    return self.resolve()
  File "/home/pasi/.pyenv/versions/3.7.2/lib/python3.7/site-packages/pkg_resources/__init__.py", line 2338, in resolve
    module = __import__(self.module_name, fromlist=[\'__name__\'], level=0)
ImportError: bad magic number in \'n_utils\': b\'\x03\xf3\r\n\'
```

## `ndt ec2-instance-id`

```bash
Traceback (most recent call last):
  File "/home/pasi/.pyenv/versions/3.7.2/bin/ndt", line 11, in <module>
    load_entry_point(\'nameless-deploy-tools\', \'console_scripts\', \'ndt\')()
  File "/home/pasi/.pyenv/versions/3.7.2/lib/python3.7/site-packages/pkg_resources/__init__.py", line 484, in load_entry_point
    return get_distribution(dist).load_entry_point(group, name)
  File "/home/pasi/.pyenv/versions/3.7.2/lib/python3.7/site-packages/pkg_resources/__init__.py", line 2714, in load_entry_point
    return ep.load()
  File "/home/pasi/.pyenv/versions/3.7.2/lib/python3.7/site-packages/pkg_resources/__init__.py", line 2332, in load
    return self.resolve()
  File "/home/pasi/.pyenv/versions/3.7.2/lib/python3.7/site-packages/pkg_resources/__init__.py", line 2338, in resolve
    module = __import__(self.module_name, fromlist=[\'__name__\'], level=0)
ImportError: bad magic number in \'n_utils\': b\'\x03\xf3\r\n\'
```

## `ndt ec2-region`

```bash
Traceback (most recent call last):
  File "/home/pasi/.pyenv/versions/3.7.2/bin/ndt", line 11, in <module>
    load_entry_point(\'nameless-deploy-tools\', \'console_scripts\', \'ndt\')()
  File "/home/pasi/.pyenv/versions/3.7.2/lib/python3.7/site-packages/pkg_resources/__init__.py", line 484, in load_entry_point
    return get_distribution(dist).load_entry_point(group, name)
  File "/home/pasi/.pyenv/versions/3.7.2/lib/python3.7/site-packages/pkg_resources/__init__.py", line 2714, in load_entry_point
    return ep.load()
  File "/home/pasi/.pyenv/versions/3.7.2/lib/python3.7/site-packages/pkg_resources/__init__.py", line 2332, in load
    return self.resolve()
  File "/home/pasi/.pyenv/versions/3.7.2/lib/python3.7/site-packages/pkg_resources/__init__.py", line 2338, in resolve
    module = __import__(self.module_name, fromlist=[\'__name__\'], level=0)
ImportError: bad magic number in \'n_utils\': b\'\x03\xf3\r\n\'
```

## `ndt ec2-wait-for-metadata`

```bash
Traceback (most recent call last):
  File "/home/pasi/.pyenv/versions/3.7.2/bin/ndt", line 11, in <module>
    load_entry_point(\'nameless-deploy-tools\', \'console_scripts\', \'ndt\')()
  File "/home/pasi/.pyenv/versions/3.7.2/lib/python3.7/site-packages/pkg_resources/__init__.py", line 484, in load_entry_point
    return get_distribution(dist).load_entry_point(group, name)
  File "/home/pasi/.pyenv/versions/3.7.2/lib/python3.7/site-packages/pkg_resources/__init__.py", line 2714, in load_entry_point
    return ep.load()
  File "/home/pasi/.pyenv/versions/3.7.2/lib/python3.7/site-packages/pkg_resources/__init__.py", line 2332, in load
    return self.resolve()
  File "/home/pasi/.pyenv/versions/3.7.2/lib/python3.7/site-packages/pkg_resources/__init__.py", line 2338, in resolve
    module = __import__(self.module_name, fromlist=[\'__name__\'], level=0)
ImportError: bad magic number in \'n_utils\': b\'\x03\xf3\r\n\'
```

## `ndt ecr-ensure-repo`

```bash
Traceback (most recent call last):
  File "/home/pasi/.pyenv/versions/3.7.2/bin/ndt", line 11, in <module>
    load_entry_point(\'nameless-deploy-tools\', \'console_scripts\', \'ndt\')()
  File "/home/pasi/.pyenv/versions/3.7.2/lib/python3.7/site-packages/pkg_resources/__init__.py", line 484, in load_entry_point
    return get_distribution(dist).load_entry_point(group, name)
  File "/home/pasi/.pyenv/versions/3.7.2/lib/python3.7/site-packages/pkg_resources/__init__.py", line 2714, in load_entry_point
    return ep.load()
  File "/home/pasi/.pyenv/versions/3.7.2/lib/python3.7/site-packages/pkg_resources/__init__.py", line 2332, in load
    return self.resolve()
  File "/home/pasi/.pyenv/versions/3.7.2/lib/python3.7/site-packages/pkg_resources/__init__.py", line 2338, in resolve
    module = __import__(self.module_name, fromlist=[\'__name__\'], level=0)
ImportError: bad magic number in \'n_utils\': b\'\x03\xf3\r\n\'
```

## `ndt ecr-repo-uri`

```bash
Traceback (most recent call last):
  File "/home/pasi/.pyenv/versions/3.7.2/bin/ndt", line 11, in <module>
    load_entry_point(\'nameless-deploy-tools\', \'console_scripts\', \'ndt\')()
  File "/home/pasi/.pyenv/versions/3.7.2/lib/python3.7/site-packages/pkg_resources/__init__.py", line 484, in load_entry_point
    return get_distribution(dist).load_entry_point(group, name)
  File "/home/pasi/.pyenv/versions/3.7.2/lib/python3.7/site-packages/pkg_resources/__init__.py", line 2714, in load_entry_point
    return ep.load()
  File "/home/pasi/.pyenv/versions/3.7.2/lib/python3.7/site-packages/pkg_resources/__init__.py", line 2332, in load
    return self.resolve()
  File "/home/pasi/.pyenv/versions/3.7.2/lib/python3.7/site-packages/pkg_resources/__init__.py", line 2338, in resolve
    module = __import__(self.module_name, fromlist=[\'__name__\'], level=0)
ImportError: bad magic number in \'n_utils\': b\'\x03\xf3\r\n\'
```

## `ndt enable-profile`

```bash
Traceback (most recent call last):
  File "/home/pasi/.pyenv/versions/3.7.2/bin/ndt", line 11, in <module>
    load_entry_point(\'nameless-deploy-tools\', \'console_scripts\', \'ndt\')()
  File "/home/pasi/.pyenv/versions/3.7.2/lib/python3.7/site-packages/pkg_resources/__init__.py", line 484, in load_entry_point
    return get_distribution(dist).load_entry_point(group, name)
  File "/home/pasi/.pyenv/versions/3.7.2/lib/python3.7/site-packages/pkg_resources/__init__.py", line 2714, in load_entry_point
    return ep.load()
  File "/home/pasi/.pyenv/versions/3.7.2/lib/python3.7/site-packages/pkg_resources/__init__.py", line 2332, in load
    return self.resolve()
  File "/home/pasi/.pyenv/versions/3.7.2/lib/python3.7/site-packages/pkg_resources/__init__.py", line 2338, in resolve
    module = __import__(self.module_name, fromlist=[\'__name__\'], level=0)
ImportError: bad magic number in \'n_utils\': b\'\x03\xf3\r\n\'
```

## `ndt get-images`

```bash
Traceback (most recent call last):
  File "/home/pasi/.pyenv/versions/3.7.2/bin/ndt", line 11, in <module>
    load_entry_point(\'nameless-deploy-tools\', \'console_scripts\', \'ndt\')()
  File "/home/pasi/.pyenv/versions/3.7.2/lib/python3.7/site-packages/pkg_resources/__init__.py", line 484, in load_entry_point
    return get_distribution(dist).load_entry_point(group, name)
  File "/home/pasi/.pyenv/versions/3.7.2/lib/python3.7/site-packages/pkg_resources/__init__.py", line 2714, in load_entry_point
    return ep.load()
  File "/home/pasi/.pyenv/versions/3.7.2/lib/python3.7/site-packages/pkg_resources/__init__.py", line 2332, in load
    return self.resolve()
  File "/home/pasi/.pyenv/versions/3.7.2/lib/python3.7/site-packages/pkg_resources/__init__.py", line 2338, in resolve
    module = __import__(self.module_name, fromlist=[\'__name__\'], level=0)
ImportError: bad magic number in \'n_utils\': b\'\x03\xf3\r\n\'
```

## `ndt interpolate-file`

```bash
Traceback (most recent call last):
  File "/home/pasi/.pyenv/versions/3.7.2/bin/ndt", line 11, in <module>
    load_entry_point(\'nameless-deploy-tools\', \'console_scripts\', \'ndt\')()
  File "/home/pasi/.pyenv/versions/3.7.2/lib/python3.7/site-packages/pkg_resources/__init__.py", line 484, in load_entry_point
    return get_distribution(dist).load_entry_point(group, name)
  File "/home/pasi/.pyenv/versions/3.7.2/lib/python3.7/site-packages/pkg_resources/__init__.py", line 2714, in load_entry_point
    return ep.load()
  File "/home/pasi/.pyenv/versions/3.7.2/lib/python3.7/site-packages/pkg_resources/__init__.py", line 2332, in load
    return self.resolve()
  File "/home/pasi/.pyenv/versions/3.7.2/lib/python3.7/site-packages/pkg_resources/__init__.py", line 2338, in resolve
    module = __import__(self.module_name, fromlist=[\'__name__\'], level=0)
ImportError: bad magic number in \'n_utils\': b\'\x03\xf3\r\n\'
```

## `ndt json-to-yaml`

```bash
Traceback (most recent call last):
  File "/home/pasi/.pyenv/versions/3.7.2/bin/ndt", line 11, in <module>
    load_entry_point(\'nameless-deploy-tools\', \'console_scripts\', \'ndt\')()
  File "/home/pasi/.pyenv/versions/3.7.2/lib/python3.7/site-packages/pkg_resources/__init__.py", line 484, in load_entry_point
    return get_distribution(dist).load_entry_point(group, name)
  File "/home/pasi/.pyenv/versions/3.7.2/lib/python3.7/site-packages/pkg_resources/__init__.py", line 2714, in load_entry_point
    return ep.load()
  File "/home/pasi/.pyenv/versions/3.7.2/lib/python3.7/site-packages/pkg_resources/__init__.py", line 2332, in load
    return self.resolve()
  File "/home/pasi/.pyenv/versions/3.7.2/lib/python3.7/site-packages/pkg_resources/__init__.py", line 2338, in resolve
    module = __import__(self.module_name, fromlist=[\'__name__\'], level=0)
ImportError: bad magic number in \'n_utils\': b\'\x03\xf3\r\n\'
```

## `ndt latest-snapshot`

```bash
Traceback (most recent call last):
  File "/home/pasi/.pyenv/versions/3.7.2/bin/ndt", line 11, in <module>
    load_entry_point(\'nameless-deploy-tools\', \'console_scripts\', \'ndt\')()
  File "/home/pasi/.pyenv/versions/3.7.2/lib/python3.7/site-packages/pkg_resources/__init__.py", line 484, in load_entry_point
    return get_distribution(dist).load_entry_point(group, name)
  File "/home/pasi/.pyenv/versions/3.7.2/lib/python3.7/site-packages/pkg_resources/__init__.py", line 2714, in load_entry_point
    return ep.load()
  File "/home/pasi/.pyenv/versions/3.7.2/lib/python3.7/site-packages/pkg_resources/__init__.py", line 2332, in load
    return self.resolve()
  File "/home/pasi/.pyenv/versions/3.7.2/lib/python3.7/site-packages/pkg_resources/__init__.py", line 2338, in resolve
    module = __import__(self.module_name, fromlist=[\'__name__\'], level=0)
ImportError: bad magic number in \'n_utils\': b\'\x03\xf3\r\n\'
```

## `ndt list-components`

```bash
Traceback (most recent call last):
  File "/home/pasi/.pyenv/versions/3.7.2/bin/ndt", line 11, in <module>
    load_entry_point(\'nameless-deploy-tools\', \'console_scripts\', \'ndt\')()
  File "/home/pasi/.pyenv/versions/3.7.2/lib/python3.7/site-packages/pkg_resources/__init__.py", line 484, in load_entry_point
    return get_distribution(dist).load_entry_point(group, name)
  File "/home/pasi/.pyenv/versions/3.7.2/lib/python3.7/site-packages/pkg_resources/__init__.py", line 2714, in load_entry_point
    return ep.load()
  File "/home/pasi/.pyenv/versions/3.7.2/lib/python3.7/site-packages/pkg_resources/__init__.py", line 2332, in load
    return self.resolve()
  File "/home/pasi/.pyenv/versions/3.7.2/lib/python3.7/site-packages/pkg_resources/__init__.py", line 2338, in resolve
    module = __import__(self.module_name, fromlist=[\'__name__\'], level=0)
ImportError: bad magic number in \'n_utils\': b\'\x03\xf3\r\n\'
```

## `ndt list-file-to-json`

```bash
Traceback (most recent call last):
  File "/home/pasi/.pyenv/versions/3.7.2/bin/ndt", line 11, in <module>
    load_entry_point(\'nameless-deploy-tools\', \'console_scripts\', \'ndt\')()
  File "/home/pasi/.pyenv/versions/3.7.2/lib/python3.7/site-packages/pkg_resources/__init__.py", line 484, in load_entry_point
    return get_distribution(dist).load_entry_point(group, name)
  File "/home/pasi/.pyenv/versions/3.7.2/lib/python3.7/site-packages/pkg_resources/__init__.py", line 2714, in load_entry_point
    return ep.load()
  File "/home/pasi/.pyenv/versions/3.7.2/lib/python3.7/site-packages/pkg_resources/__init__.py", line 2332, in load
    return self.resolve()
  File "/home/pasi/.pyenv/versions/3.7.2/lib/python3.7/site-packages/pkg_resources/__init__.py", line 2338, in resolve
    module = __import__(self.module_name, fromlist=[\'__name__\'], level=0)
ImportError: bad magic number in \'n_utils\': b\'\x03\xf3\r\n\'
```

## `ndt list-jobs`

```bash
Traceback (most recent call last):
  File "/home/pasi/.pyenv/versions/3.7.2/bin/ndt", line 11, in <module>
    load_entry_point(\'nameless-deploy-tools\', \'console_scripts\', \'ndt\')()
  File "/home/pasi/.pyenv/versions/3.7.2/lib/python3.7/site-packages/pkg_resources/__init__.py", line 484, in load_entry_point
    return get_distribution(dist).load_entry_point(group, name)
  File "/home/pasi/.pyenv/versions/3.7.2/lib/python3.7/site-packages/pkg_resources/__init__.py", line 2714, in load_entry_point
    return ep.load()
  File "/home/pasi/.pyenv/versions/3.7.2/lib/python3.7/site-packages/pkg_resources/__init__.py", line 2332, in load
    return self.resolve()
  File "/home/pasi/.pyenv/versions/3.7.2/lib/python3.7/site-packages/pkg_resources/__init__.py", line 2338, in resolve
    module = __import__(self.module_name, fromlist=[\'__name__\'], level=0)
ImportError: bad magic number in \'n_utils\': b\'\x03\xf3\r\n\'
```

## `ndt load-parameters`

```bash
Traceback (most recent call last):
  File "/home/pasi/.pyenv/versions/3.7.2/bin/ndt", line 11, in <module>
    load_entry_point(\'nameless-deploy-tools\', \'console_scripts\', \'ndt\')()
  File "/home/pasi/.pyenv/versions/3.7.2/lib/python3.7/site-packages/pkg_resources/__init__.py", line 484, in load_entry_point
    return get_distribution(dist).load_entry_point(group, name)
  File "/home/pasi/.pyenv/versions/3.7.2/lib/python3.7/site-packages/pkg_resources/__init__.py", line 2714, in load_entry_point
    return ep.load()
  File "/home/pasi/.pyenv/versions/3.7.2/lib/python3.7/site-packages/pkg_resources/__init__.py", line 2332, in load
    return self.resolve()
  File "/home/pasi/.pyenv/versions/3.7.2/lib/python3.7/site-packages/pkg_resources/__init__.py", line 2338, in resolve
    module = __import__(self.module_name, fromlist=[\'__name__\'], level=0)
ImportError: bad magic number in \'n_utils\': b\'\x03\xf3\r\n\'
```

## `ndt logs`

```bash
Traceback (most recent call last):
  File "/home/pasi/.pyenv/versions/3.7.2/bin/ndt", line 11, in <module>
    load_entry_point(\'nameless-deploy-tools\', \'console_scripts\', \'ndt\')()
  File "/home/pasi/.pyenv/versions/3.7.2/lib/python3.7/site-packages/pkg_resources/__init__.py", line 484, in load_entry_point
    return get_distribution(dist).load_entry_point(group, name)
  File "/home/pasi/.pyenv/versions/3.7.2/lib/python3.7/site-packages/pkg_resources/__init__.py", line 2714, in load_entry_point
    return ep.load()
  File "/home/pasi/.pyenv/versions/3.7.2/lib/python3.7/site-packages/pkg_resources/__init__.py", line 2332, in load
    return self.resolve()
  File "/home/pasi/.pyenv/versions/3.7.2/lib/python3.7/site-packages/pkg_resources/__init__.py", line 2338, in resolve
    module = __import__(self.module_name, fromlist=[\'__name__\'], level=0)
ImportError: bad magic number in \'n_utils\': b\'\x03\xf3\r\n\'
```

## `ndt mfa-add-token`

```bash
Traceback (most recent call last):
  File "/home/pasi/.pyenv/versions/3.7.2/bin/ndt", line 11, in <module>
    load_entry_point(\'nameless-deploy-tools\', \'console_scripts\', \'ndt\')()
  File "/home/pasi/.pyenv/versions/3.7.2/lib/python3.7/site-packages/pkg_resources/__init__.py", line 484, in load_entry_point
    return get_distribution(dist).load_entry_point(group, name)
  File "/home/pasi/.pyenv/versions/3.7.2/lib/python3.7/site-packages/pkg_resources/__init__.py", line 2714, in load_entry_point
    return ep.load()
  File "/home/pasi/.pyenv/versions/3.7.2/lib/python3.7/site-packages/pkg_resources/__init__.py", line 2332, in load
    return self.resolve()
  File "/home/pasi/.pyenv/versions/3.7.2/lib/python3.7/site-packages/pkg_resources/__init__.py", line 2338, in resolve
    module = __import__(self.module_name, fromlist=[\'__name__\'], level=0)
ImportError: bad magic number in \'n_utils\': b\'\x03\xf3\r\n\'
```

## `ndt mfa-backup`

```bash
Traceback (most recent call last):
  File "/home/pasi/.pyenv/versions/3.7.2/bin/ndt", line 11, in <module>
    load_entry_point(\'nameless-deploy-tools\', \'console_scripts\', \'ndt\')()
  File "/home/pasi/.pyenv/versions/3.7.2/lib/python3.7/site-packages/pkg_resources/__init__.py", line 484, in load_entry_point
    return get_distribution(dist).load_entry_point(group, name)
  File "/home/pasi/.pyenv/versions/3.7.2/lib/python3.7/site-packages/pkg_resources/__init__.py", line 2714, in load_entry_point
    return ep.load()
  File "/home/pasi/.pyenv/versions/3.7.2/lib/python3.7/site-packages/pkg_resources/__init__.py", line 2332, in load
    return self.resolve()
  File "/home/pasi/.pyenv/versions/3.7.2/lib/python3.7/site-packages/pkg_resources/__init__.py", line 2338, in resolve
    module = __import__(self.module_name, fromlist=[\'__name__\'], level=0)
ImportError: bad magic number in \'n_utils\': b\'\x03\xf3\r\n\'
```

## `ndt mfa-code`

```bash
Traceback (most recent call last):
  File "/home/pasi/.pyenv/versions/3.7.2/bin/ndt", line 11, in <module>
    load_entry_point(\'nameless-deploy-tools\', \'console_scripts\', \'ndt\')()
  File "/home/pasi/.pyenv/versions/3.7.2/lib/python3.7/site-packages/pkg_resources/__init__.py", line 484, in load_entry_point
    return get_distribution(dist).load_entry_point(group, name)
  File "/home/pasi/.pyenv/versions/3.7.2/lib/python3.7/site-packages/pkg_resources/__init__.py", line 2714, in load_entry_point
    return ep.load()
  File "/home/pasi/.pyenv/versions/3.7.2/lib/python3.7/site-packages/pkg_resources/__init__.py", line 2332, in load
    return self.resolve()
  File "/home/pasi/.pyenv/versions/3.7.2/lib/python3.7/site-packages/pkg_resources/__init__.py", line 2338, in resolve
    module = __import__(self.module_name, fromlist=[\'__name__\'], level=0)
ImportError: bad magic number in \'n_utils\': b\'\x03\xf3\r\n\'
```

## `ndt mfa-delete-token`

```bash
Traceback (most recent call last):
  File "/home/pasi/.pyenv/versions/3.7.2/bin/ndt", line 11, in <module>
    load_entry_point(\'nameless-deploy-tools\', \'console_scripts\', \'ndt\')()
  File "/home/pasi/.pyenv/versions/3.7.2/lib/python3.7/site-packages/pkg_resources/__init__.py", line 484, in load_entry_point
    return get_distribution(dist).load_entry_point(group, name)
  File "/home/pasi/.pyenv/versions/3.7.2/lib/python3.7/site-packages/pkg_resources/__init__.py", line 2714, in load_entry_point
    return ep.load()
  File "/home/pasi/.pyenv/versions/3.7.2/lib/python3.7/site-packages/pkg_resources/__init__.py", line 2332, in load
    return self.resolve()
  File "/home/pasi/.pyenv/versions/3.7.2/lib/python3.7/site-packages/pkg_resources/__init__.py", line 2338, in resolve
    module = __import__(self.module_name, fromlist=[\'__name__\'], level=0)
ImportError: bad magic number in \'n_utils\': b\'\x03\xf3\r\n\'
```

## `ndt mfa-qrcode`

```bash
Traceback (most recent call last):
  File "/home/pasi/.pyenv/versions/3.7.2/bin/ndt", line 11, in <module>
    load_entry_point(\'nameless-deploy-tools\', \'console_scripts\', \'ndt\')()
  File "/home/pasi/.pyenv/versions/3.7.2/lib/python3.7/site-packages/pkg_resources/__init__.py", line 484, in load_entry_point
    return get_distribution(dist).load_entry_point(group, name)
  File "/home/pasi/.pyenv/versions/3.7.2/lib/python3.7/site-packages/pkg_resources/__init__.py", line 2714, in load_entry_point
    return ep.load()
  File "/home/pasi/.pyenv/versions/3.7.2/lib/python3.7/site-packages/pkg_resources/__init__.py", line 2332, in load
    return self.resolve()
  File "/home/pasi/.pyenv/versions/3.7.2/lib/python3.7/site-packages/pkg_resources/__init__.py", line 2338, in resolve
    module = __import__(self.module_name, fromlist=[\'__name__\'], level=0)
ImportError: bad magic number in \'n_utils\': b\'\x03\xf3\r\n\'
```

## `ndt print-create-instructions`

```bash
Traceback (most recent call last):
  File "/home/pasi/.pyenv/versions/3.7.2/bin/ndt", line 11, in <module>
    load_entry_point(\'nameless-deploy-tools\', \'console_scripts\', \'ndt\')()
  File "/home/pasi/.pyenv/versions/3.7.2/lib/python3.7/site-packages/pkg_resources/__init__.py", line 484, in load_entry_point
    return get_distribution(dist).load_entry_point(group, name)
  File "/home/pasi/.pyenv/versions/3.7.2/lib/python3.7/site-packages/pkg_resources/__init__.py", line 2714, in load_entry_point
    return ep.load()
  File "/home/pasi/.pyenv/versions/3.7.2/lib/python3.7/site-packages/pkg_resources/__init__.py", line 2332, in load
    return self.resolve()
  File "/home/pasi/.pyenv/versions/3.7.2/lib/python3.7/site-packages/pkg_resources/__init__.py", line 2338, in resolve
    module = __import__(self.module_name, fromlist=[\'__name__\'], level=0)
ImportError: bad magic number in \'n_utils\': b\'\x03\xf3\r\n\'
```

## `ndt profile-expiry-to-env`

```bash
Traceback (most recent call last):
  File "/home/pasi/.pyenv/versions/3.7.2/bin/ndt", line 11, in <module>
    load_entry_point(\'nameless-deploy-tools\', \'console_scripts\', \'ndt\')()
  File "/home/pasi/.pyenv/versions/3.7.2/lib/python3.7/site-packages/pkg_resources/__init__.py", line 484, in load_entry_point
    return get_distribution(dist).load_entry_point(group, name)
  File "/home/pasi/.pyenv/versions/3.7.2/lib/python3.7/site-packages/pkg_resources/__init__.py", line 2714, in load_entry_point
    return ep.load()
  File "/home/pasi/.pyenv/versions/3.7.2/lib/python3.7/site-packages/pkg_resources/__init__.py", line 2332, in load
    return self.resolve()
  File "/home/pasi/.pyenv/versions/3.7.2/lib/python3.7/site-packages/pkg_resources/__init__.py", line 2338, in resolve
    module = __import__(self.module_name, fromlist=[\'__name__\'], level=0)
ImportError: bad magic number in \'n_utils\': b\'\x03\xf3\r\n\'
```

## `ndt profile-to-env`

```bash
Traceback (most recent call last):
  File "/home/pasi/.pyenv/versions/3.7.2/bin/ndt", line 11, in <module>
    load_entry_point(\'nameless-deploy-tools\', \'console_scripts\', \'ndt\')()
  File "/home/pasi/.pyenv/versions/3.7.2/lib/python3.7/site-packages/pkg_resources/__init__.py", line 484, in load_entry_point
    return get_distribution(dist).load_entry_point(group, name)
  File "/home/pasi/.pyenv/versions/3.7.2/lib/python3.7/site-packages/pkg_resources/__init__.py", line 2714, in load_entry_point
    return ep.load()
  File "/home/pasi/.pyenv/versions/3.7.2/lib/python3.7/site-packages/pkg_resources/__init__.py", line 2332, in load
    return self.resolve()
  File "/home/pasi/.pyenv/versions/3.7.2/lib/python3.7/site-packages/pkg_resources/__init__.py", line 2338, in resolve
    module = __import__(self.module_name, fromlist=[\'__name__\'], level=0)
ImportError: bad magic number in \'n_utils\': b\'\x03\xf3\r\n\'
```

## `ndt promote-image`

```bash
Traceback (most recent call last):
  File "/home/pasi/.pyenv/versions/3.7.2/bin/ndt", line 11, in <module>
    load_entry_point(\'nameless-deploy-tools\', \'console_scripts\', \'ndt\')()
  File "/home/pasi/.pyenv/versions/3.7.2/lib/python3.7/site-packages/pkg_resources/__init__.py", line 484, in load_entry_point
    return get_distribution(dist).load_entry_point(group, name)
  File "/home/pasi/.pyenv/versions/3.7.2/lib/python3.7/site-packages/pkg_resources/__init__.py", line 2714, in load_entry_point
    return ep.load()
  File "/home/pasi/.pyenv/versions/3.7.2/lib/python3.7/site-packages/pkg_resources/__init__.py", line 2332, in load
    return self.resolve()
  File "/home/pasi/.pyenv/versions/3.7.2/lib/python3.7/site-packages/pkg_resources/__init__.py", line 2338, in resolve
    module = __import__(self.module_name, fromlist=[\'__name__\'], level=0)
ImportError: bad magic number in \'n_utils\': b\'\x03\xf3\r\n\'
```

## `ndt pytail`

```bash
Traceback (most recent call last):
  File "/home/pasi/.pyenv/versions/3.7.2/bin/ndt", line 11, in <module>
    load_entry_point(\'nameless-deploy-tools\', \'console_scripts\', \'ndt\')()
  File "/home/pasi/.pyenv/versions/3.7.2/lib/python3.7/site-packages/pkg_resources/__init__.py", line 484, in load_entry_point
    return get_distribution(dist).load_entry_point(group, name)
  File "/home/pasi/.pyenv/versions/3.7.2/lib/python3.7/site-packages/pkg_resources/__init__.py", line 2714, in load_entry_point
    return ep.load()
  File "/home/pasi/.pyenv/versions/3.7.2/lib/python3.7/site-packages/pkg_resources/__init__.py", line 2332, in load
    return self.resolve()
  File "/home/pasi/.pyenv/versions/3.7.2/lib/python3.7/site-packages/pkg_resources/__init__.py", line 2338, in resolve
    module = __import__(self.module_name, fromlist=[\'__name__\'], level=0)
ImportError: bad magic number in \'n_utils\': b\'\x03\xf3\r\n\'
```

## `ndt read-profile-expiry`

```bash
Traceback (most recent call last):
  File "/home/pasi/.pyenv/versions/3.7.2/bin/ndt", line 11, in <module>
    load_entry_point(\'nameless-deploy-tools\', \'console_scripts\', \'ndt\')()
  File "/home/pasi/.pyenv/versions/3.7.2/lib/python3.7/site-packages/pkg_resources/__init__.py", line 484, in load_entry_point
    return get_distribution(dist).load_entry_point(group, name)
  File "/home/pasi/.pyenv/versions/3.7.2/lib/python3.7/site-packages/pkg_resources/__init__.py", line 2714, in load_entry_point
    return ep.load()
  File "/home/pasi/.pyenv/versions/3.7.2/lib/python3.7/site-packages/pkg_resources/__init__.py", line 2332, in load
    return self.resolve()
  File "/home/pasi/.pyenv/versions/3.7.2/lib/python3.7/site-packages/pkg_resources/__init__.py", line 2338, in resolve
    module = __import__(self.module_name, fromlist=[\'__name__\'], level=0)
ImportError: bad magic number in \'n_utils\': b\'\x03\xf3\r\n\'
```

## `ndt region`

```bash
Traceback (most recent call last):
  File "/home/pasi/.pyenv/versions/3.7.2/bin/ndt", line 11, in <module>
    load_entry_point(\'nameless-deploy-tools\', \'console_scripts\', \'ndt\')()
  File "/home/pasi/.pyenv/versions/3.7.2/lib/python3.7/site-packages/pkg_resources/__init__.py", line 484, in load_entry_point
    return get_distribution(dist).load_entry_point(group, name)
  File "/home/pasi/.pyenv/versions/3.7.2/lib/python3.7/site-packages/pkg_resources/__init__.py", line 2714, in load_entry_point
    return ep.load()
  File "/home/pasi/.pyenv/versions/3.7.2/lib/python3.7/site-packages/pkg_resources/__init__.py", line 2332, in load
    return self.resolve()
  File "/home/pasi/.pyenv/versions/3.7.2/lib/python3.7/site-packages/pkg_resources/__init__.py", line 2338, in resolve
    module = __import__(self.module_name, fromlist=[\'__name__\'], level=0)
ImportError: bad magic number in \'n_utils\': b\'\x03\xf3\r\n\'
```

## `ndt register-private-dns`

```bash
Traceback (most recent call last):
  File "/home/pasi/.pyenv/versions/3.7.2/bin/ndt", line 11, in <module>
    load_entry_point(\'nameless-deploy-tools\', \'console_scripts\', \'ndt\')()
  File "/home/pasi/.pyenv/versions/3.7.2/lib/python3.7/site-packages/pkg_resources/__init__.py", line 484, in load_entry_point
    return get_distribution(dist).load_entry_point(group, name)
  File "/home/pasi/.pyenv/versions/3.7.2/lib/python3.7/site-packages/pkg_resources/__init__.py", line 2714, in load_entry_point
    return ep.load()
  File "/home/pasi/.pyenv/versions/3.7.2/lib/python3.7/site-packages/pkg_resources/__init__.py", line 2332, in load
    return self.resolve()
  File "/home/pasi/.pyenv/versions/3.7.2/lib/python3.7/site-packages/pkg_resources/__init__.py", line 2338, in resolve
    module = __import__(self.module_name, fromlist=[\'__name__\'], level=0)
ImportError: bad magic number in \'n_utils\': b\'\x03\xf3\r\n\'
```

## `ndt session-to-env`

```bash
Traceback (most recent call last):
  File "/home/pasi/.pyenv/versions/3.7.2/bin/ndt", line 11, in <module>
    load_entry_point(\'nameless-deploy-tools\', \'console_scripts\', \'ndt\')()
  File "/home/pasi/.pyenv/versions/3.7.2/lib/python3.7/site-packages/pkg_resources/__init__.py", line 484, in load_entry_point
    return get_distribution(dist).load_entry_point(group, name)
  File "/home/pasi/.pyenv/versions/3.7.2/lib/python3.7/site-packages/pkg_resources/__init__.py", line 2714, in load_entry_point
    return ep.load()
  File "/home/pasi/.pyenv/versions/3.7.2/lib/python3.7/site-packages/pkg_resources/__init__.py", line 2332, in load
    return self.resolve()
  File "/home/pasi/.pyenv/versions/3.7.2/lib/python3.7/site-packages/pkg_resources/__init__.py", line 2338, in resolve
    module = __import__(self.module_name, fromlist=[\'__name__\'], level=0)
ImportError: bad magic number in \'n_utils\': b\'\x03\xf3\r\n\'
```

## `ndt setup-cli`

```bash
Traceback (most recent call last):
  File "/home/pasi/.pyenv/versions/3.7.2/bin/ndt", line 11, in <module>
    load_entry_point(\'nameless-deploy-tools\', \'console_scripts\', \'ndt\')()
  File "/home/pasi/.pyenv/versions/3.7.2/lib/python3.7/site-packages/pkg_resources/__init__.py", line 484, in load_entry_point
    return get_distribution(dist).load_entry_point(group, name)
  File "/home/pasi/.pyenv/versions/3.7.2/lib/python3.7/site-packages/pkg_resources/__init__.py", line 2714, in load_entry_point
    return ep.load()
  File "/home/pasi/.pyenv/versions/3.7.2/lib/python3.7/site-packages/pkg_resources/__init__.py", line 2332, in load
    return self.resolve()
  File "/home/pasi/.pyenv/versions/3.7.2/lib/python3.7/site-packages/pkg_resources/__init__.py", line 2338, in resolve
    module = __import__(self.module_name, fromlist=[\'__name__\'], level=0)
ImportError: bad magic number in \'n_utils\': b\'\x03\xf3\r\n\'
```

## `ndt share-to-another-region`

```bash
Traceback (most recent call last):
  File "/home/pasi/.pyenv/versions/3.7.2/bin/ndt", line 11, in <module>
    load_entry_point(\'nameless-deploy-tools\', \'console_scripts\', \'ndt\')()
  File "/home/pasi/.pyenv/versions/3.7.2/lib/python3.7/site-packages/pkg_resources/__init__.py", line 484, in load_entry_point
    return get_distribution(dist).load_entry_point(group, name)
  File "/home/pasi/.pyenv/versions/3.7.2/lib/python3.7/site-packages/pkg_resources/__init__.py", line 2714, in load_entry_point
    return ep.load()
  File "/home/pasi/.pyenv/versions/3.7.2/lib/python3.7/site-packages/pkg_resources/__init__.py", line 2332, in load
    return self.resolve()
  File "/home/pasi/.pyenv/versions/3.7.2/lib/python3.7/site-packages/pkg_resources/__init__.py", line 2338, in resolve
    module = __import__(self.module_name, fromlist=[\'__name__\'], level=0)
ImportError: bad magic number in \'n_utils\': b\'\x03\xf3\r\n\'
```

## `ndt show-stack-params-and-outputs`

```bash
Traceback (most recent call last):
  File "/home/pasi/.pyenv/versions/3.7.2/bin/ndt", line 11, in <module>
    load_entry_point(\'nameless-deploy-tools\', \'console_scripts\', \'ndt\')()
  File "/home/pasi/.pyenv/versions/3.7.2/lib/python3.7/site-packages/pkg_resources/__init__.py", line 484, in load_entry_point
    return get_distribution(dist).load_entry_point(group, name)
  File "/home/pasi/.pyenv/versions/3.7.2/lib/python3.7/site-packages/pkg_resources/__init__.py", line 2714, in load_entry_point
    return ep.load()
  File "/home/pasi/.pyenv/versions/3.7.2/lib/python3.7/site-packages/pkg_resources/__init__.py", line 2332, in load
    return self.resolve()
  File "/home/pasi/.pyenv/versions/3.7.2/lib/python3.7/site-packages/pkg_resources/__init__.py", line 2338, in resolve
    module = __import__(self.module_name, fromlist=[\'__name__\'], level=0)
ImportError: bad magic number in \'n_utils\': b\'\x03\xf3\r\n\'
```

## `ndt show-terraform-params`

```bash
Traceback (most recent call last):
  File "/home/pasi/.pyenv/versions/3.7.2/bin/ndt", line 11, in <module>
    load_entry_point(\'nameless-deploy-tools\', \'console_scripts\', \'ndt\')()
  File "/home/pasi/.pyenv/versions/3.7.2/lib/python3.7/site-packages/pkg_resources/__init__.py", line 484, in load_entry_point
    return get_distribution(dist).load_entry_point(group, name)
  File "/home/pasi/.pyenv/versions/3.7.2/lib/python3.7/site-packages/pkg_resources/__init__.py", line 2714, in load_entry_point
    return ep.load()
  File "/home/pasi/.pyenv/versions/3.7.2/lib/python3.7/site-packages/pkg_resources/__init__.py", line 2332, in load
    return self.resolve()
  File "/home/pasi/.pyenv/versions/3.7.2/lib/python3.7/site-packages/pkg_resources/__init__.py", line 2338, in resolve
    module = __import__(self.module_name, fromlist=[\'__name__\'], level=0)
ImportError: bad magic number in \'n_utils\': b\'\x03\xf3\r\n\'
```

## `ndt snapshot-from-volume`

```bash
Traceback (most recent call last):
  File "/home/pasi/.pyenv/versions/3.7.2/bin/ndt", line 11, in <module>
    load_entry_point(\'nameless-deploy-tools\', \'console_scripts\', \'ndt\')()
  File "/home/pasi/.pyenv/versions/3.7.2/lib/python3.7/site-packages/pkg_resources/__init__.py", line 484, in load_entry_point
    return get_distribution(dist).load_entry_point(group, name)
  File "/home/pasi/.pyenv/versions/3.7.2/lib/python3.7/site-packages/pkg_resources/__init__.py", line 2714, in load_entry_point
    return ep.load()
  File "/home/pasi/.pyenv/versions/3.7.2/lib/python3.7/site-packages/pkg_resources/__init__.py", line 2332, in load
    return self.resolve()
  File "/home/pasi/.pyenv/versions/3.7.2/lib/python3.7/site-packages/pkg_resources/__init__.py", line 2338, in resolve
    module = __import__(self.module_name, fromlist=[\'__name__\'], level=0)
ImportError: bad magic number in \'n_utils\': b\'\x03\xf3\r\n\'
```

## `ndt terraform-pull-state`

```bash
Traceback (most recent call last):
  File "/home/pasi/.pyenv/versions/3.7.2/bin/ndt", line 11, in <module>
    load_entry_point(\'nameless-deploy-tools\', \'console_scripts\', \'ndt\')()
  File "/home/pasi/.pyenv/versions/3.7.2/lib/python3.7/site-packages/pkg_resources/__init__.py", line 484, in load_entry_point
    return get_distribution(dist).load_entry_point(group, name)
  File "/home/pasi/.pyenv/versions/3.7.2/lib/python3.7/site-packages/pkg_resources/__init__.py", line 2714, in load_entry_point
    return ep.load()
  File "/home/pasi/.pyenv/versions/3.7.2/lib/python3.7/site-packages/pkg_resources/__init__.py", line 2332, in load
    return self.resolve()
  File "/home/pasi/.pyenv/versions/3.7.2/lib/python3.7/site-packages/pkg_resources/__init__.py", line 2338, in resolve
    module = __import__(self.module_name, fromlist=[\'__name__\'], level=0)
ImportError: bad magic number in \'n_utils\': b\'\x03\xf3\r\n\'
```

## `ndt undeploy-cdk`

```bash
Traceback (most recent call last):
  File "/home/pasi/.pyenv/versions/3.7.2/bin/ndt", line 11, in <module>
    load_entry_point(\'nameless-deploy-tools\', \'console_scripts\', \'ndt\')()
  File "/home/pasi/.pyenv/versions/3.7.2/lib/python3.7/site-packages/pkg_resources/__init__.py", line 484, in load_entry_point
    return get_distribution(dist).load_entry_point(group, name)
  File "/home/pasi/.pyenv/versions/3.7.2/lib/python3.7/site-packages/pkg_resources/__init__.py", line 2714, in load_entry_point
    return ep.load()
  File "/home/pasi/.pyenv/versions/3.7.2/lib/python3.7/site-packages/pkg_resources/__init__.py", line 2332, in load
    return self.resolve()
  File "/home/pasi/.pyenv/versions/3.7.2/lib/python3.7/site-packages/pkg_resources/__init__.py", line 2338, in resolve
    module = __import__(self.module_name, fromlist=[\'__name__\'], level=0)
ImportError: bad magic number in \'n_utils\': b\'\x03\xf3\r\n\'
```

## `ndt undeploy-serverless`

```bash
Traceback (most recent call last):
  File "/home/pasi/.pyenv/versions/3.7.2/bin/ndt", line 11, in <module>
    load_entry_point(\'nameless-deploy-tools\', \'console_scripts\', \'ndt\')()
  File "/home/pasi/.pyenv/versions/3.7.2/lib/python3.7/site-packages/pkg_resources/__init__.py", line 484, in load_entry_point
    return get_distribution(dist).load_entry_point(group, name)
  File "/home/pasi/.pyenv/versions/3.7.2/lib/python3.7/site-packages/pkg_resources/__init__.py", line 2714, in load_entry_point
    return ep.load()
  File "/home/pasi/.pyenv/versions/3.7.2/lib/python3.7/site-packages/pkg_resources/__init__.py", line 2332, in load
    return self.resolve()
  File "/home/pasi/.pyenv/versions/3.7.2/lib/python3.7/site-packages/pkg_resources/__init__.py", line 2338, in resolve
    module = __import__(self.module_name, fromlist=[\'__name__\'], level=0)
ImportError: bad magic number in \'n_utils\': b\'\x03\xf3\r\n\'
```

## `ndt undeploy-stack`

```bash
Traceback (most recent call last):
  File "/home/pasi/.pyenv/versions/3.7.2/bin/ndt", line 11, in <module>
    load_entry_point(\'nameless-deploy-tools\', \'console_scripts\', \'ndt\')()
  File "/home/pasi/.pyenv/versions/3.7.2/lib/python3.7/site-packages/pkg_resources/__init__.py", line 484, in load_entry_point
    return get_distribution(dist).load_entry_point(group, name)
  File "/home/pasi/.pyenv/versions/3.7.2/lib/python3.7/site-packages/pkg_resources/__init__.py", line 2714, in load_entry_point
    return ep.load()
  File "/home/pasi/.pyenv/versions/3.7.2/lib/python3.7/site-packages/pkg_resources/__init__.py", line 2332, in load
    return self.resolve()
  File "/home/pasi/.pyenv/versions/3.7.2/lib/python3.7/site-packages/pkg_resources/__init__.py", line 2338, in resolve
    module = __import__(self.module_name, fromlist=[\'__name__\'], level=0)
ImportError: bad magic number in \'n_utils\': b\'\x03\xf3\r\n\'
```

## `ndt undeploy-terraform`

```bash
Traceback (most recent call last):
  File "/home/pasi/.pyenv/versions/3.7.2/bin/ndt", line 11, in <module>
    load_entry_point(\'nameless-deploy-tools\', \'console_scripts\', \'ndt\')()
  File "/home/pasi/.pyenv/versions/3.7.2/lib/python3.7/site-packages/pkg_resources/__init__.py", line 484, in load_entry_point
    return get_distribution(dist).load_entry_point(group, name)
  File "/home/pasi/.pyenv/versions/3.7.2/lib/python3.7/site-packages/pkg_resources/__init__.py", line 2714, in load_entry_point
    return ep.load()
  File "/home/pasi/.pyenv/versions/3.7.2/lib/python3.7/site-packages/pkg_resources/__init__.py", line 2332, in load
    return self.resolve()
  File "/home/pasi/.pyenv/versions/3.7.2/lib/python3.7/site-packages/pkg_resources/__init__.py", line 2338, in resolve
    module = __import__(self.module_name, fromlist=[\'__name__\'], level=0)
ImportError: bad magic number in \'n_utils\': b\'\x03\xf3\r\n\'
```

## `ndt upsert-cloudfront-records`

```bash
Traceback (most recent call last):
  File "/home/pasi/.pyenv/versions/3.7.2/bin/ndt", line 11, in <module>
    load_entry_point(\'nameless-deploy-tools\', \'console_scripts\', \'ndt\')()
  File "/home/pasi/.pyenv/versions/3.7.2/lib/python3.7/site-packages/pkg_resources/__init__.py", line 484, in load_entry_point
    return get_distribution(dist).load_entry_point(group, name)
  File "/home/pasi/.pyenv/versions/3.7.2/lib/python3.7/site-packages/pkg_resources/__init__.py", line 2714, in load_entry_point
    return ep.load()
  File "/home/pasi/.pyenv/versions/3.7.2/lib/python3.7/site-packages/pkg_resources/__init__.py", line 2332, in load
    return self.resolve()
  File "/home/pasi/.pyenv/versions/3.7.2/lib/python3.7/site-packages/pkg_resources/__init__.py", line 2338, in resolve
    module = __import__(self.module_name, fromlist=[\'__name__\'], level=0)
ImportError: bad magic number in \'n_utils\': b\'\x03\xf3\r\n\'
```

## `ndt volume-from-snapshot`

```bash
Traceback (most recent call last):
  File "/home/pasi/.pyenv/versions/3.7.2/bin/ndt", line 11, in <module>
    load_entry_point(\'nameless-deploy-tools\', \'console_scripts\', \'ndt\')()
  File "/home/pasi/.pyenv/versions/3.7.2/lib/python3.7/site-packages/pkg_resources/__init__.py", line 484, in load_entry_point
    return get_distribution(dist).load_entry_point(group, name)
  File "/home/pasi/.pyenv/versions/3.7.2/lib/python3.7/site-packages/pkg_resources/__init__.py", line 2714, in load_entry_point
    return ep.load()
  File "/home/pasi/.pyenv/versions/3.7.2/lib/python3.7/site-packages/pkg_resources/__init__.py", line 2332, in load
    return self.resolve()
  File "/home/pasi/.pyenv/versions/3.7.2/lib/python3.7/site-packages/pkg_resources/__init__.py", line 2338, in resolve
    module = __import__(self.module_name, fromlist=[\'__name__\'], level=0)
ImportError: bad magic number in \'n_utils\': b\'\x03\xf3\r\n\'
```

## `ndt yaml-to-json`

```bash
Traceback (most recent call last):
  File "/home/pasi/.pyenv/versions/3.7.2/bin/ndt", line 11, in <module>
    load_entry_point(\'nameless-deploy-tools\', \'console_scripts\', \'ndt\')()
  File "/home/pasi/.pyenv/versions/3.7.2/lib/python3.7/site-packages/pkg_resources/__init__.py", line 484, in load_entry_point
    return get_distribution(dist).load_entry_point(group, name)
  File "/home/pasi/.pyenv/versions/3.7.2/lib/python3.7/site-packages/pkg_resources/__init__.py", line 2714, in load_entry_point
    return ep.load()
  File "/home/pasi/.pyenv/versions/3.7.2/lib/python3.7/site-packages/pkg_resources/__init__.py", line 2332, in load
    return self.resolve()
  File "/home/pasi/.pyenv/versions/3.7.2/lib/python3.7/site-packages/pkg_resources/__init__.py", line 2338, in resolve
    module = __import__(self.module_name, fromlist=[\'__name__\'], level=0)
ImportError: bad magic number in \'n_utils\': b\'\x03\xf3\r\n\'
```

## `ndt yaml-to-yaml`

```bash
Traceback (most recent call last):
  File "/home/pasi/.pyenv/versions/3.7.2/bin/ndt", line 11, in <module>
    load_entry_point(\'nameless-deploy-tools\', \'console_scripts\', \'ndt\')()
  File "/home/pasi/.pyenv/versions/3.7.2/lib/python3.7/site-packages/pkg_resources/__init__.py", line 484, in load_entry_point
    return get_distribution(dist).load_entry_point(group, name)
  File "/home/pasi/.pyenv/versions/3.7.2/lib/python3.7/site-packages/pkg_resources/__init__.py", line 2714, in load_entry_point
    return ep.load()
  File "/home/pasi/.pyenv/versions/3.7.2/lib/python3.7/site-packages/pkg_resources/__init__.py", line 2332, in load
    return self.resolve()
  File "/home/pasi/.pyenv/versions/3.7.2/lib/python3.7/site-packages/pkg_resources/__init__.py", line 2338, in resolve
    module = __import__(self.module_name, fromlist=[\'__name__\'], level=0)
ImportError: bad magic number in \'n_utils\': b\'\x03\xf3\r\n\'
```

## `[ndt ]associate-eip`

```bash
Traceback (most recent call last):
  File "/home/pasi/.pyenv/versions/3.7.2/bin/associate-eip", line 11, in <module>
    load_entry_point(\'nameless-deploy-tools\', \'console_scripts\', \'associate-eip\')()
  File "/home/pasi/.pyenv/versions/3.7.2/lib/python3.7/site-packages/pkg_resources/__init__.py", line 484, in load_entry_point
    return get_distribution(dist).load_entry_point(group, name)
  File "/home/pasi/.pyenv/versions/3.7.2/lib/python3.7/site-packages/pkg_resources/__init__.py", line 2714, in load_entry_point
    return ep.load()
  File "/home/pasi/.pyenv/versions/3.7.2/lib/python3.7/site-packages/pkg_resources/__init__.py", line 2332, in load
    return self.resolve()
  File "/home/pasi/.pyenv/versions/3.7.2/lib/python3.7/site-packages/pkg_resources/__init__.py", line 2338, in resolve
    module = __import__(self.module_name, fromlist=[\'__name__\'], level=0)
ImportError: bad magic number in \'n_utils\': b\'\x03\xf3\r\n\'
```

## `[ndt ]cf-logs-to-cloudwatch`

```bash
usage: cf-logs-to-cloudwatch [-h] [-g GROUP] [-s STREAM] file

Read a file and send rows to cloudwatch and keep following the end for new
data. The log group will be the stack name that created instance if not given
as an argument. The logstream will be the instance id and filename if not
given as an argument. Group and stream aare created if they do not exist.

positional arguments:
  file                  File to follow

optional arguments:
  -h, --help            show this help message and exit
  -g GROUP, --group GROUP
                        Log group to log to. Defaults to the stack name that
                        created the instance if not given and instance is
                        created with a CloudFormation stack
  -s STREAM, --stream STREAM
                        The log stream name to log to. The instance id and
                        filename if not given
```

## `[ndt ]ec2-associate-eip`

```bash
Traceback (most recent call last):
  File "/home/pasi/.pyenv/versions/3.7.2/bin/ec2-associate-eip", line 11, in <module>
    load_entry_point(\'nameless-deploy-tools\', \'console_scripts\', \'ec2-associate-eip\')()
  File "/home/pasi/.pyenv/versions/3.7.2/lib/python3.7/site-packages/pkg_resources/__init__.py", line 484, in load_entry_point
    return get_distribution(dist).load_entry_point(group, name)
  File "/home/pasi/.pyenv/versions/3.7.2/lib/python3.7/site-packages/pkg_resources/__init__.py", line 2714, in load_entry_point
    return ep.load()
  File "/home/pasi/.pyenv/versions/3.7.2/lib/python3.7/site-packages/pkg_resources/__init__.py", line 2332, in load
    return self.resolve()
  File "/home/pasi/.pyenv/versions/3.7.2/lib/python3.7/site-packages/pkg_resources/__init__.py", line 2338, in resolve
    module = __import__(self.module_name, fromlist=[\'__name__\'], level=0)
ImportError: bad magic number in \'n_utils\': b\'\x03\xf3\r\n\'
```

## `[ndt ]logs-to-cloudwatch`

```bash
usage: logs-to-cloudwatch [-h] [-g GROUP] [-s STREAM] file

Read a file and send rows to cloudwatch and keep following the end for new
data. The log group will be the stack name that created instance if not given
as an argument. The logstream will be the instance id and filename if not
given as an argument. Group and stream aare created if they do not exist.

positional arguments:
  file                  File to follow

optional arguments:
  -h, --help            show this help message and exit
  -g GROUP, --group GROUP
                        Log group to log to. Defaults to the stack name that
                        created the instance if not given and instance is
                        created with a CloudFormation stack
  -s STREAM, --stream STREAM
                        The log stream name to log to. The instance id and
                        filename if not given
```

## `[ndt ]n-include`

```bash
Traceback (most recent call last):
  File "/home/pasi/.pyenv/versions/3.7.2/bin/n-include", line 11, in <module>
    load_entry_point(\'nameless-deploy-tools\', \'console_scripts\', \'n-include\')()
  File "/home/pasi/.pyenv/versions/3.7.2/lib/python3.7/site-packages/pkg_resources/__init__.py", line 484, in load_entry_point
    return get_distribution(dist).load_entry_point(group, name)
  File "/home/pasi/.pyenv/versions/3.7.2/lib/python3.7/site-packages/pkg_resources/__init__.py", line 2714, in load_entry_point
    return ep.load()
  File "/home/pasi/.pyenv/versions/3.7.2/lib/python3.7/site-packages/pkg_resources/__init__.py", line 2332, in load
    return self.resolve()
  File "/home/pasi/.pyenv/versions/3.7.2/lib/python3.7/site-packages/pkg_resources/__init__.py", line 2338, in resolve
    module = __import__(self.module_name, fromlist=[\'__name__\'], level=0)
ImportError: bad magic number in \'n_utils\': b\'\x03\xf3\r\n\'
```

## `[ndt ]n-include-all`

```bash
Traceback (most recent call last):
  File "/home/pasi/.pyenv/versions/3.7.2/bin/n-include-all", line 11, in <module>
    load_entry_point(\'nameless-deploy-tools\', \'console_scripts\', \'n-include-all\')()
  File "/home/pasi/.pyenv/versions/3.7.2/lib/python3.7/site-packages/pkg_resources/__init__.py", line 484, in load_entry_point
    return get_distribution(dist).load_entry_point(group, name)
  File "/home/pasi/.pyenv/versions/3.7.2/lib/python3.7/site-packages/pkg_resources/__init__.py", line 2714, in load_entry_point
    return ep.load()
  File "/home/pasi/.pyenv/versions/3.7.2/lib/python3.7/site-packages/pkg_resources/__init__.py", line 2332, in load
    return self.resolve()
  File "/home/pasi/.pyenv/versions/3.7.2/lib/python3.7/site-packages/pkg_resources/__init__.py", line 2338, in resolve
    module = __import__(self.module_name, fromlist=[\'__name__\'], level=0)
ImportError: bad magic number in \'n_utils\': b\'\x03\xf3\r\n\'
```

## `[ndt ]signal-cf-status`

```bash
usage: signal-cf-status [-h] [-r RESOURCE] status

Signal CloudFormation status to a logical resource in CloudFormation that is
either given on the command line or resolved from CloudFormation tags

positional arguments:
  status                Status to indicate: SUCCESS | FAILURE

optional arguments:
  -h, --help            show this help message and exit
  -r RESOURCE, --resource RESOURCE
                        Logical resource name to signal. Looked up from
                        cloudformation tags by default
```

## `create-shell-archive.sh`

```bash
file  one or more files to package into the archive
usage: create-shell-archive.sh [-h] [<file> ...]

Creates a self-extracting bash archive, suitable for storing in e.g. Lastpass SecureNotes
positional arguments:

optional arguments:
  -h, --help  show this help message and exit
```

## `encrypt-and-mount.sh`

```bash
Mounts a local block device as an encrypted volume. Handy for things like local database installs.
usage: encrypt-and-mount.sh [-h] blk-device mount-path


positional arguments
  blk-device  the block device you want to encrypt and mount
  mount-path  the mount point for the encrypted volume

optional arguments:
  -h, --help  show this help message and exit
```

## `ensure-letsencrypt-certs.sh`

```bash
usage: ensure-letsencrypt-certs.sh [-h] domain-name [domain-name ...]

Fetches a certificate with fetch-secrets.sh, and exits cleanly if certificate is found and valid.
Otherwise gets a new certificate from letsencrypt via DNS verification using Route53.
Requires that fetch-secrets.sh and Route53 are set up correctly.

positional arguments
  domain-name   The domain(s) you want to check certificates for

optional arguments:
  -h, --help  show this help message and exit
```

## `lastpass-fetch-notes.sh`

```bash
--optional  marks that following files will not fail and exit the script in they do not exist
usage: lasptass-fetch-notes.sh [-h] mode file [file ...] [--optional file ...]

Fetches secure notes from lastpass that match the basename of each listed file.
Files specified after --optional won\'t fail if the file does not exist.

positional arguments
  mode   the file mode for the downloaded files
  file   the file(s) to download. The source will be the note that matches the basename of the file

optional arguments:
  -h, --help  show this help message and exit
```

## `lpssh`

```bash
usage: lpssh [-h] [-k key-name] user@example.com

Fetches key mappings from lastpass, downloads mapped keys into a local ssh-agent and starts
an ssh session using those credentials.

positional arguments
  user@example.com   The user and host to match in "my-ssh-mappings" secure note
                     and to log into once keys are set up.

optional arguments:
  -k,         key name in lastpass to use if you don\'t want to use a mapping
  -h, --help  show this help message and exit
```

## `mount-and-format.sh`

```bash
Mounts a local block device as an encrypted volume. Handy for things like local database installs.
usage: mount-and-format.sh [-h] blk-device mount-path


positional arguments
  blk-device  the block device you want to mount and formant
  mount-path  the mount point for the volume

optional arguments:
  -h, --help  show this help message and exit
```

## `setup-fetch-secrets.sh`

```bash
Please run as root
usage: setup-fetch-secrets.sh [-h] <lpass|s3|vault>

Sets up a global fetch-secrets.sh that fetches secrets from either LastPass, S3 or nitor-vault

positional arguments
  lpass|s3|vault   the selected secrets backend.

optional arguments:
  -h, --help  show this help message and exit exit 1
```

## `ssh-hostkeys-collect.sh`

```bash
usage: ssh-hostkeys-collect.sh [-h] hostname

Creates a <hostname>-ssh-hostkeys.sh archive in the current directory containing
ssh host keys to preserve the identity of a server over image upgrades.

positional arguments
  hostname   the name of the host used to store the keys. Typically the hostname is what
             instance userdata scripts will use to look for the keys

optional arguments:
  -h, --help  show this help message and exit
```

