# NDT Command Reference

## `ndt account-id`

```bash
Traceback (most recent call last):
  File "/home/pasi/.pyenv/versions/3.7.2/bin/ndt", line 11, in <module>
    load_entry_point(\'nameless-deploy-tools\', \'console_scripts\', \'ndt\')()
  File "/home/pasi/.pyenv/versions/3.7.2/lib/python3.7/site-packages/pkg_resources/__init__.py", line 484, in load_entry_point
    return get_distribution(dist).load_entry_point(group, name)
  File "/home/pasi/.pyenv/versions/3.7.2/lib/python3.7/site-packages/pkg_resources/__init__.py", line 2714, in load_entry_point
    return ep.load()
  File "/home/pasi/.pyenv/versions/3.7.2/lib/python3.7/site-packages/pkg_resources/__init__.py", line 2332, in load
    return self.resolve()
  File "/home/pasi/.pyenv/versions/3.7.2/lib/python3.7/site-packages/pkg_resources/__init__.py", line 2338, in resolve
    module = __import__(self.module_name, fromlist=[\'__name__\'], level=0)
ImportError: bad magic number in \'n_utils\': b\'\x03\xf3\r\n\'
```

## `ndt add-deployer-server`

```bash
Traceback (most recent call last):
  File "/home/pasi/.pyenv/versions/3.7.2/bin/ndt", line 11, in <module>
    load_entry_point(\'nameless-deploy-tools\', \'console_scripts\', \'ndt\')()
  File "/home/pasi/.pyenv/versions/3.7.2/lib/python3.7/site-packages/pkg_resources/__init__.py", line 484, in load_entry_point
    return get_distribution(dist).load_entry_point(group, name)
  File "/home/pasi/.pyenv/versions/3.7.2/lib/python3.7/site-packages/pkg_resources/__init__.py", line 2714, in load_entry_point
    return ep.load()
  File "/home/pasi/.pyenv/versions/3.7.2/lib/python3.7/site-packages/pkg_resources/__init__.py", line 2332, in load
    return self.resolve()
  File "/home/pasi/.pyenv/versions/3.7.2/lib/python3.7/site-packages/pkg_resources/__init__.py", line 2338, in resolve
    module = __import__(self.module_name, fromlist=[\'__name__\'], level=0)
ImportError: bad magic number in \'n_utils\': b\'\x03\xf3\r\n\'
```

## `ndt assume-role`

```bash
Traceback (most recent call last):
  File "/home/pasi/.pyenv/versions/3.7.2/bin/ndt", line 11, in <module>
    load_entry_point(\'nameless-deploy-tools\', \'console_scripts\', \'ndt\')()
  File "/home/pasi/.pyenv/versions/3.7.2/lib/python3.7/site-packages/pkg_resources/__init__.py", line 484, in load_entry_point
    return get_distribution(dist).load_entry_point(group, name)
  File "/home/pasi/.pyenv/versions/3.7.2/lib/python3.7/site-packages/pkg_resources/__init__.py", line 2714, in load_entry_point
    return ep.load()
  File "/home/pasi/.pyenv/versions/3.7.2/lib/python3.7/site-packages/pkg_resources/__init__.py", line 2332, in load
    return self.resolve()
  File "/home/pasi/.pyenv/versions/3.7.2/lib/python3.7/site-packages/pkg_resources/__init__.py", line 2338, in resolve
    module = __import__(self.module_name, fromlist=[\'__name__\'], level=0)
ImportError: bad magic number in \'n_utils\': b\'\x03\xf3\r\n\'
```

## `ndt assumed-role-name`

```bash
Traceback (most recent call last):
  File "/home/pasi/.pyenv/versions/3.7.2/bin/ndt", line 11, in <module>
    load_entry_point(\'nameless-deploy-tools\', \'console_scripts\', \'ndt\')()
  File "/home/pasi/.pyenv/versions/3.7.2/lib/python3.7/site-packages/pkg_resources/__init__.py", line 484, in load_entry_point
    return get_distribution(dist).load_entry_point(group, name)
  File "/home/pasi/.pyenv/versions/3.7.2/lib/python3.7/site-packages/pkg_resources/__init__.py", line 2714, in load_entry_point
    return ep.load()
  File "/home/pasi/.pyenv/versions/3.7.2/lib/python3.7/site-packages/pkg_resources/__init__.py", line 2332, in load
    return self.resolve()
  File "/home/pasi/.pyenv/versions/3.7.2/lib/python3.7/site-packages/pkg_resources/__init__.py", line 2338, in resolve
    module = __import__(self.module_name, fromlist=[\'__name__\'], level=0)
ImportError: bad magic number in \'n_utils\': b\'\x03\xf3\r\n\'
```

## `ndt bake-docker`

```bash
Traceback (most recent call last):
  File "/home/pasi/.pyenv/versions/3.7.2/bin/ndt", line 11, in <module>
    load_entry_point(\'nameless-deploy-tools\', \'console_scripts\', \'ndt\')()
  File "/home/pasi/.pyenv/versions/3.7.2/lib/python3.7/site-packages/pkg_resources/__init__.py", line 484, in load_entry_point
    return get_distribution(dist).load_entry_point(group, name)
  File "/home/pasi/.pyenv/versions/3.7.2/lib/python3.7/site-packages/pkg_resources/__init__.py", line 2714, in load_entry_point
    return ep.load()
  File "/home/pasi/.pyenv/versions/3.7.2/lib/python3.7/site-packages/pkg_resources/__init__.py", line 2332, in load
    return self.resolve()
  File "/home/pasi/.pyenv/versions/3.7.2/lib/python3.7/site-packages/pkg_resources/__init__.py", line 2338, in resolve
    module = __import__(self.module_name, fromlist=[\'__name__\'], level=0)
ImportError: bad magic number in \'n_utils\': b\'\x03\xf3\r\n\'
```

## `ndt bake-image`

```bash
Traceback (most recent call last):
  File "/home/pasi/.pyenv/versions/3.7.2/bin/ndt", line 11, in <module>
    load_entry_point(\'nameless-deploy-tools\', \'console_scripts\', \'ndt\')()
  File "/home/pasi/.pyenv/versions/3.7.2/lib/python3.7/site-packages/pkg_resources/__init__.py", line 484, in load_entry_point
    return get_distribution(dist).load_entry_point(group, name)
  File "/home/pasi/.pyenv/versions/3.7.2/lib/python3.7/site-packages/pkg_resources/__init__.py", line 2714, in load_entry_point
    return ep.load()
  File "/home/pasi/.pyenv/versions/3.7.2/lib/python3.7/site-packages/pkg_resources/__init__.py", line 2332, in load
    return self.resolve()
  File "/home/pasi/.pyenv/versions/3.7.2/lib/python3.7/site-packages/pkg_resources/__init__.py", line 2338, in resolve
    module = __import__(self.module_name, fromlist=[\'__name__\'], level=0)
ImportError: bad magic number in \'n_utils\': b\'\x03\xf3\r\n\'
```

## `ndt cf-delete-stack`

```bash
Traceback (most recent call last):
  File "/home/pasi/.pyenv/versions/3.7.2/bin/ndt", line 11, in <module>
    load_entry_point(\'nameless-deploy-tools\', \'console_scripts\', \'ndt\')()
  File "/home/pasi/.pyenv/versions/3.7.2/lib/python3.7/site-packages/pkg_resources/__init__.py", line 484, in load_entry_point
    return get_distribution(dist).load_entry_point(group, name)
  File "/home/pasi/.pyenv/versions/3.7.2/lib/python3.7/site-packages/pkg_resources/__init__.py", line 2714, in load_entry_point
    return ep.load()
  File "/home/pasi/.pyenv/versions/3.7.2/lib/python3.7/site-packages/pkg_resources/__init__.py", line 2332, in load
    return self.resolve()
  File "/home/pasi/.pyenv/versions/3.7.2/lib/python3.7/site-packages/pkg_resources/__init__.py", line 2338, in resolve
    module = __import__(self.module_name, fromlist=[\'__name__\'], level=0)
ImportError: bad magic number in \'n_utils\': b\'\x03\xf3\r\n\'
```

## `ndt cf-follow-logs`

```bash
Traceback (most recent call last):
  File "/home/pasi/.pyenv/versions/3.7.2/bin/ndt", line 11, in <module>
    load_entry_point(\'nameless-deploy-tools\', \'console_scripts\', \'ndt\')()
  File "/home/pasi/.pyenv/versions/3.7.2/lib/python3.7/site-packages/pkg_resources/__init__.py", line 484, in load_entry_point
    return get_distribution(dist).load_entry_point(group, name)
  File "/home/pasi/.pyenv/versions/3.7.2/lib/python3.7/site-packages/pkg_resources/__init__.py", line 2714, in load_entry_point
    return ep.load()
  File "/home/pasi/.pyenv/versions/3.7.2/lib/python3.7/site-packages/pkg_resources/__init__.py", line 2332, in load
    return self.resolve()
  File "/home/pasi/.pyenv/versions/3.7.2/lib/python3.7/site-packages/pkg_resources/__init__.py", line 2338, in resolve
    module = __import__(self.module_name, fromlist=[\'__name__\'], level=0)
ImportError: bad magic number in \'n_utils\': b\'\x03\xf3\r\n\'
```

## `ndt cf-get-parameter`

```bash
Traceback (most recent call last):
  File "/home/pasi/.pyenv/versions/3.7.2/bin/ndt", line 11, in <module>
    load_entry_point(\'nameless-deploy-tools\', \'console_scripts\', \'ndt\')()
  File "/home/pasi/.pyenv/versions/3.7.2/lib/python3.7/site-packages/pkg_resources/__init__.py", line 484, in load_entry_point
    return get_distribution(dist).load_entry_point(group, name)
  File "/home/pasi/.pyenv/versions/3.7.2/lib/python3.7/site-packages/pkg_resources/__init__.py", line 2714, in load_entry_point
    return ep.load()
  File "/home/pasi/.pyenv/versions/3.7.2/lib/python3.7/site-packages/pkg_resources/__init__.py", line 2332, in load
    return self.resolve()
  File "/home/pasi/.pyenv/versions/3.7.2/lib/python3.7/site-packages/pkg_resources/__init__.py", line 2338, in resolve
    module = __import__(self.module_name, fromlist=[\'__name__\'], level=0)
ImportError: bad magic number in \'n_utils\': b\'\x03\xf3\r\n\'
```

## `ndt cf-logical-id`

```bash
Traceback (most recent call last):
  File "/home/pasi/.pyenv/versions/3.7.2/bin/ndt", line 11, in <module>
    load_entry_point(\'nameless-deploy-tools\', \'console_scripts\', \'ndt\')()
  File "/home/pasi/.pyenv/versions/3.7.2/lib/python3.7/site-packages/pkg_resources/__init__.py", line 484, in load_entry_point
    return get_distribution(dist).load_entry_point(group, name)
  File "/home/pasi/.pyenv/versions/3.7.2/lib/python3.7/site-packages/pkg_resources/__init__.py", line 2714, in load_entry_point
    return ep.load()
  File "/home/pasi/.pyenv/versions/3.7.2/lib/python3.7/site-packages/pkg_resources/__init__.py", line 2332, in load
    return self.resolve()
  File "/home/pasi/.pyenv/versions/3.7.2/lib/python3.7/site-packages/pkg_resources/__init__.py", line 2338, in resolve
    module = __import__(self.module_name, fromlist=[\'__name__\'], level=0)
ImportError: bad magic number in \'n_utils\': b\'\x03\xf3\r\n\'
```

## `ndt cf-region`

```bash
Traceback (most recent call last):
  File "/home/pasi/.pyenv/versions/3.7.2/bin/ndt", line 11, in <module>
    load_entry_point(\'nameless-deploy-tools\', \'console_scripts\', \'ndt\')()
  File "/home/pasi/.pyenv/versions/3.7.2/lib/python3.7/site-packages/pkg_resources/__init__.py", line 484, in load_entry_point
    return get_distribution(dist).load_entry_point(group, name)
  File "/home/pasi/.pyenv/versions/3.7.2/lib/python3.7/site-packages/pkg_resources/__init__.py", line 2714, in load_entry_point
    return ep.load()
  File "/home/pasi/.pyenv/versions/3.7.2/lib/python3.7/site-packages/pkg_resources/__init__.py", line 2332, in load
    return self.resolve()
  File "/home/pasi/.pyenv/versions/3.7.2/lib/python3.7/site-packages/pkg_resources/__init__.py", line 2338, in resolve
    module = __import__(self.module_name, fromlist=[\'__name__\'], level=0)
ImportError: bad magic number in \'n_utils\': b\'\x03\xf3\r\n\'
```

## `ndt cf-signal-status`

```bash
Traceback (most recent call last):
  File "/home/pasi/.pyenv/versions/3.7.2/bin/ndt", line 11, in <module>
    load_entry_point(\'nameless-deploy-tools\', \'console_scripts\', \'ndt\')()
  File "/home/pasi/.pyenv/versions/3.7.2/lib/python3.7/site-packages/pkg_resources/__init__.py", line 484, in load_entry_point
    return get_distribution(dist).load_entry_point(group, name)
  File "/home/pasi/.pyenv/versions/3.7.2/lib/python3.7/site-packages/pkg_resources/__init__.py", line 2714, in load_entry_point
    return ep.load()
  File "/home/pasi/.pyenv/versions/3.7.2/lib/python3.7/site-packages/pkg_resources/__init__.py", line 2332, in load
    return self.resolve()
  File "/home/pasi/.pyenv/versions/3.7.2/lib/python3.7/site-packages/pkg_resources/__init__.py", line 2338, in resolve
    module = __import__(self.module_name, fromlist=[\'__name__\'], level=0)
ImportError: bad magic number in \'n_utils\': b\'\x03\xf3\r\n\'
```

## `ndt cf-stack-id`

```bash
Traceback (most recent call last):
  File "/home/pasi/.pyenv/versions/3.7.2/bin/ndt", line 11, in <module>
    load_entry_point(\'nameless-deploy-tools\', \'console_scripts\', \'ndt\')()
  File "/home/pasi/.pyenv/versions/3.7.2/lib/python3.7/site-packages/pkg_resources/__init__.py", line 484, in load_entry_point
    return get_distribution(dist).load_entry_point(group, name)
  File "/home/pasi/.pyenv/versions/3.7.2/lib/python3.7/site-packages/pkg_resources/__init__.py", line 2714, in load_entry_point
    return ep.load()
  File "/home/pasi/.pyenv/versions/3.7.2/lib/python3.7/site-packages/pkg_resources/__init__.py", line 2332, in load
    return self.resolve()
  File "/home/pasi/.pyenv/versions/3.7.2/lib/python3.7/site-packages/pkg_resources/__init__.py", line 2338, in resolve
    module = __import__(self.module_name, fromlist=[\'__name__\'], level=0)
ImportError: bad magic number in \'n_utils\': b\'\x03\xf3\r\n\'
```

## `ndt cf-stack-name`

```bash
Traceback (most recent call last):
  File "/home/pasi/.pyenv/versions/3.7.2/bin/ndt", line 11, in <module>
    load_entry_point(\'nameless-deploy-tools\', \'console_scripts\', \'ndt\')()
  File "/home/pasi/.pyenv/versions/3.7.2/lib/python3.7/site-packages/pkg_resources/__init__.py", line 484, in load_entry_point
    return get_distribution(dist).load_entry_point(group, name)
  File "/home/pasi/.pyenv/versions/3.7.2/lib/python3.7/site-packages/pkg_resources/__init__.py", line 2714, in load_entry_point
    return ep.load()
  File "/home/pasi/.pyenv/versions/3.7.2/lib/python3.7/site-packages/pkg_resources/__init__.py", line 2332, in load
    return self.resolve()
  File "/home/pasi/.pyenv/versions/3.7.2/lib/python3.7/site-packages/pkg_resources/__init__.py", line 2338, in resolve
    module = __import__(self.module_name, fromlist=[\'__name__\'], level=0)
ImportError: bad magic number in \'n_utils\': b\'\x03\xf3\r\n\'
```

## `ndt create-account`

```bash
Traceback (most recent call last):
  File "/home/pasi/.pyenv/versions/3.7.2/bin/ndt", line 11, in <module>
    load_entry_point(\'nameless-deploy-tools\', \'console_scripts\', \'ndt\')()
  File "/home/pasi/.pyenv/versions/3.7.2/lib/python3.7/site-packages/pkg_resources/__init__.py", line 484, in load_entry_point
    return get_distribution(dist).load_entry_point(group, name)
  File "/home/pasi/.pyenv/versions/3.7.2/lib/python3.7/site-packages/pkg_resources/__init__.py", line 2714, in load_entry_point
    return ep.load()
  File "/home/pasi/.pyenv/versions/3.7.2/lib/python3.7/site-packages/pkg_resources/__init__.py", line 2332, in load
    return self.resolve()
  File "/home/pasi/.pyenv/versions/3.7.2/lib/python3.7/site-packages/pkg_resources/__init__.py", line 2338, in resolve
    module = __import__(self.module_name, fromlist=[\'__name__\'], level=0)
ImportError: bad magic number in \'n_utils\': b\'\x03\xf3\r\n\'
```

## `ndt create-stack`

```bash
Traceback (most recent call last):
  File "/home/pasi/.pyenv/versions/3.7.2/bin/ndt", line 11, in <module>
    load_entry_point(\'nameless-deploy-tools\', \'console_scripts\', \'ndt\')()
  File "/home/pasi/.pyenv/versions/3.7.2/lib/python3.7/site-packages/pkg_resources/__init__.py", line 484, in load_entry_point
    return get_distribution(dist).load_entry_point(group, name)
  File "/home/pasi/.pyenv/versions/3.7.2/lib/python3.7/site-packages/pkg_resources/__init__.py", line 2714, in load_entry_point
    return ep.load()
  File "/home/pasi/.pyenv/versions/3.7.2/lib/python3.7/site-packages/pkg_resources/__init__.py", line 2332, in load
    return self.resolve()
  File "/home/pasi/.pyenv/versions/3.7.2/lib/python3.7/site-packages/pkg_resources/__init__.py", line 2338, in resolve
    module = __import__(self.module_name, fromlist=[\'__name__\'], level=0)
ImportError: bad magic number in \'n_utils\': b\'\x03\xf3\r\n\'
```

## `ndt deploy-cdk`

```bash
Traceback (most recent call last):
  File "/home/pasi/.pyenv/versions/3.7.2/bin/ndt", line 11, in <module>
    load_entry_point(\'nameless-deploy-tools\', \'console_scripts\', \'ndt\')()
  File "/home/pasi/.pyenv/versions/3.7.2/lib/python3.7/site-packages/pkg_resources/__init__.py", line 484, in load_entry_point
    return get_distribution(dist).load_entry_point(group, name)
  File "/home/pasi/.pyenv/versions/3.7.2/lib/python3.7/site-packages/pkg_resources/__init__.py", line 2714, in load_entry_point
    return ep.load()
  File "/home/pasi/.pyenv/versions/3.7.2/lib/python3.7/site-packages/pkg_resources/__init__.py", line 2332, in load
    return self.resolve()
  File "/home/pasi/.pyenv/versions/3.7.2/lib/python3.7/site-packages/pkg_resources/__init__.py", line 2338, in resolve
    module = __import__(self.module_name, fromlist=[\'__name__\'], level=0)
ImportError: bad magic number in \'n_utils\': b\'\x03\xf3\r\n\'
```

## `ndt deploy-serverless`

```bash
Traceback (most recent call last):
  File "/home/pasi/.pyenv/versions/3.7.2/bin/ndt", line 11, in <module>
    load_entry_point(\'nameless-deploy-tools\', \'console_scripts\', \'ndt\')()
  File "/home/pasi/.pyenv/versions/3.7.2/lib/python3.7/site-packages/pkg_resources/__init__.py", line 484, in load_entry_point
    return get_distribution(dist).load_entry_point(group, name)
  File "/home/pasi/.pyenv/versions/3.7.2/lib/python3.7/site-packages/pkg_resources/__init__.py", line 2714, in load_entry_point
    return ep.load()
  File "/home/pasi/.pyenv/versions/3.7.2/lib/python3.7/site-packages/pkg_resources/__init__.py", line 2332, in load
    return self.resolve()
  File "/home/pasi/.pyenv/versions/3.7.2/lib/python3.7/site-packages/pkg_resources/__init__.py", line 2338, in resolve
    module = __import__(self.module_name, fromlist=[\'__name__\'], level=0)
ImportError: bad magic number in \'n_utils\': b\'\x03\xf3\r\n\'
```

## `ndt deploy-stack`

```bash
Traceback (most recent call last):
  File "/home/pasi/.pyenv/versions/3.7.2/bin/ndt", line 11, in <module>
    load_entry_point(\'nameless-deploy-tools\', \'console_scripts\', \'ndt\')()
  File "/home/pasi/.pyenv/versions/3.7.2/lib/python3.7/site-packages/pkg_resources/__init__.py", line 484, in load_entry_point
    return get_distribution(dist).load_entry_point(group, name)
  File "/home/pasi/.pyenv/versions/3.7.2/lib/python3.7/site-packages/pkg_resources/__init__.py", line 2714, in load_entry_point
    return ep.load()
  File "/home/pasi/.pyenv/versions/3.7.2/lib/python3.7/site-packages/pkg_resources/__init__.py", line 2332, in load
    return self.resolve()
  File "/home/pasi/.pyenv/versions/3.7.2/lib/python3.7/site-packages/pkg_resources/__init__.py", line 2338, in resolve
    module = __import__(self.module_name, fromlist=[\'__name__\'], level=0)
ImportError: bad magic number in \'n_utils\': b\'\x03\xf3\r\n\'
```

## `ndt deploy-terraform`

```bash
Traceback (most recent call last):
  File "/home/pasi/.pyenv/versions/3.7.2/bin/ndt", line 11, in <module>
    load_entry_point(\'nameless-deploy-tools\', \'console_scripts\', \'ndt\')()
  File "/home/pasi/.pyenv/versions/3.7.2/lib/python3.7/site-packages/pkg_resources/__init__.py", line 484, in load_entry_point
    return get_distribution(dist).load_entry_point(group, name)
  File "/home/pasi/.pyenv/versions/3.7.2/lib/python3.7/site-packages/pkg_resources/__init__.py", line 2714, in load_entry_point
    return ep.load()
  File "/home/pasi/.pyenv/versions/3.7.2/lib/python3.7/site-packages/pkg_resources/__init__.py", line 2332, in load
    return self.resolve()
  File "/home/pasi/.pyenv/versions/3.7.2/lib/python3.7/site-packages/pkg_resources/__init__.py", line 2338, in resolve
    module = __import__(self.module_name, fromlist=[\'__name__\'], level=0)
ImportError: bad magic number in \'n_utils\': b\'\x03\xf3\r\n\'
```

## `ndt detach-volume`

```bash
Traceback (most recent call last):
  File "/home/pasi/.pyenv/versions/3.7.2/bin/ndt", line 11, in <module>
    load_entry_point(\'nameless-deploy-tools\', \'console_scripts\', \'ndt\')()
  File "/home/pasi/.pyenv/versions/3.7.2/lib/python3.7/site-packages/pkg_resources/__init__.py", line 484, in load_entry_point
    return get_distribution(dist).load_entry_point(group, name)
  File "/home/pasi/.pyenv/versions/3.7.2/lib/python3.7/site-packages/pkg_resources/__init__.py", line 2714, in load_entry_point
    return ep.load()
  File "/home/pasi/.pyenv/versions/3.7.2/lib/python3.7/site-packages/pkg_resources/__init__.py", line 2332, in load
    return self.resolve()
  File "/home/pasi/.pyenv/versions/3.7.2/lib/python3.7/site-packages/pkg_resources/__init__.py", line 2338, in resolve
    module = __import__(self.module_name, fromlist=[\'__name__\'], level=0)
ImportError: bad magic number in \'n_utils\': b\'\x03\xf3\r\n\'
```

## `ndt ec2-clean-snapshots`

```bash
Traceback (most recent call last):
  File "/home/pasi/.pyenv/versions/3.7.2/bin/ndt", line 11, in <module>
    load_entry_point(\'nameless-deploy-tools\', \'console_scripts\', \'ndt\')()
  File "/home/pasi/.pyenv/versions/3.7.2/lib/python3.7/site-packages/pkg_resources/__init__.py", line 484, in load_entry_point
    return get_distribution(dist).load_entry_point(group, name)
  File "/home/pasi/.pyenv/versions/3.7.2/lib/python3.7/site-packages/pkg_resources/__init__.py", line 2714, in load_entry_point
    return ep.load()
  File "/home/pasi/.pyenv/versions/3.7.2/lib/python3.7/site-packages/pkg_resources/__init__.py", line 2332, in load
    return self.resolve()
  File "/home/pasi/.pyenv/versions/3.7.2/lib/python3.7/site-packages/pkg_resources/__init__.py", line 2338, in resolve
    module = __import__(self.module_name, fromlist=[\'__name__\'], level=0)
ImportError: bad magic number in \'n_utils\': b\'\x03\xf3\r\n\'
```

## `ndt ec2-get-tag`

```bash
Traceback (most recent call last):
  File "/home/pasi/.pyenv/versions/3.7.2/bin/ndt", line 11, in <module>
    load_entry_point(\'nameless-deploy-tools\', \'console_scripts\', \'ndt\')()
  File "/home/pasi/.pyenv/versions/3.7.2/lib/python3.7/site-packages/pkg_resources/__init__.py", line 484, in load_entry_point
    return get_distribution(dist).load_entry_point(group, name)
  File "/home/pasi/.pyenv/versions/3.7.2/lib/python3.7/site-packages/pkg_resources/__init__.py", line 2714, in load_entry_point
    return ep.load()
  File "/home/pasi/.pyenv/versions/3.7.2/lib/python3.7/site-packages/pkg_resources/__init__.py", line 2332, in load
    return self.resolve()
  File "/home/pasi/.pyenv/versions/3.7.2/lib/python3.7/site-packages/pkg_resources/__init__.py", line 2338, in resolve
    module = __import__(self.module_name, fromlist=[\'__name__\'], level=0)
ImportError: bad magic number in \'n_utils\': b\'\x03\xf3\r\n\'
```

## `ndt ec2-get-userdata`

```bash
Traceback (most recent call last):
  File "/home/pasi/.pyenv/versions/3.7.2/bin/ndt", line 11, in <module>
    load_entry_point(\'nameless-deploy-tools\', \'console_scripts\', \'ndt\')()
  File "/home/pasi/.pyenv/versions/3.7.2/lib/python3.7/site-packages/pkg_resources/__init__.py", line 484, in load_entry_point
    return get_distribution(dist).load_entry_point(group, name)
  File "/home/pasi/.pyenv/versions/3.7.2/lib/python3.7/site-packages/pkg_resources/__init__.py", line 2714, in load_entry_point
    return ep.load()
  File "/home/pasi/.pyenv/versions/3.7.2/lib/python3.7/site-packages/pkg_resources/__init__.py", line 2332, in load
    return self.resolve()
  File "/home/pasi/.pyenv/versions/3.7.2/lib/python3.7/site-packages/pkg_resources/__init__.py", line 2338, in resolve
    module = __import__(self.module_name, fromlist=[\'__name__\'], level=0)
ImportError: bad magic number in \'n_utils\': b\'\x03\xf3\r\n\'
```

## `ndt ec2-instance-id`

```bash
Traceback (most recent call last):
  File "/home/pasi/.pyenv/versions/3.7.2/bin/ndt", line 11, in <module>
    load_entry_point(\'nameless-deploy-tools\', \'console_scripts\', \'ndt\')()
  File "/home/pasi/.pyenv/versions/3.7.2/lib/python3.7/site-packages/pkg_resources/__init__.py", line 484, in load_entry_point
    return get_distribution(dist).load_entry_point(group, name)
  File "/home/pasi/.pyenv/versions/3.7.2/lib/python3.7/site-packages/pkg_resources/__init__.py", line 2714, in load_entry_point
    return ep.load()
  File "/home/pasi/.pyenv/versions/3.7.2/lib/python3.7/site-packages/pkg_resources/__init__.py", line 2332, in load
    return self.resolve()
  File "/home/pasi/.pyenv/versions/3.7.2/lib/python3.7/site-packages/pkg_resources/__init__.py", line 2338, in resolve
    module = __import__(self.module_name, fromlist=[\'__name__\'], level=0)
ImportError: bad magic number in \'n_utils\': b\'\x03\xf3\r\n\'
```

## `ndt ec2-region`

```bash
Traceback (most recent call last):
  File "/home/pasi/.pyenv/versions/3.7.2/bin/ndt", line 11, in <module>
    load_entry_point(\'nameless-deploy-tools\', \'console_scripts\', \'ndt\')()
  File "/home/pasi/.pyenv/versions/3.7.2/lib/python3.7/site-packages/pkg_resources/__init__.py", line 484, in load_entry_point
    return get_distribution(dist).load_entry_point(group, name)
  File "/home/pasi/.pyenv/versions/3.7.2/lib/python3.7/site-packages/pkg_resources/__init__.py", line 2714, in load_entry_point
    return ep.load()
  File "/home/pasi/.pyenv/versions/3.7.2/lib/python3.7/site-packages/pkg_resources/__init__.py", line 2332, in load
    return self.resolve()
  File "/home/pasi/.pyenv/versions/3.7.2/lib/python3.7/site-packages/pkg_resources/__init__.py", line 2338, in resolve
    module = __import__(self.module_name, fromlist=[\'__name__\'], level=0)
ImportError: bad magic number in \'n_utils\': b\'\x03\xf3\r\n\'
```

## `ndt ec2-wait-for-metadata`

```bash
Traceback (most recent call last):
  File "/home/pasi/.pyenv/versions/3.7.2/bin/ndt", line 11, in <module>
    load_entry_point(\'nameless-deploy-tools\', \'console_scripts\', \'ndt\')()
  File "/home/pasi/.pyenv/versions/3.7.2/lib/python3.7/site-packages/pkg_resources/__init__.py", line 484, in load_entry_point
    return get_distribution(dist).load_entry_point(group, name)
  File "/home/pasi/.pyenv/versions/3.7.2/lib/python3.7/site-packages/pkg_resources/__init__.py", line 2714, in load_entry_point
    return ep.load()
  File "/home/pasi/.pyenv/versions/3.7.2/lib/python3.7/site-packages/pkg_resources/__init__.py", line 2332, in load
    return self.resolve()
  File "/home/pasi/.pyenv/versions/3.7.2/lib/python3.7/site-packages/pkg_resources/__init__.py", line 2338, in resolve
    module = __import__(self.module_name, fromlist=[\'__name__\'], level=0)
ImportError: bad magic number in \'n_utils\': b\'\x03\xf3\r\n\'
```

## `ndt ecr-ensure-repo`

```bash
Traceback (most recent call last):
  File "/home/pasi/.pyenv/versions/3.7.2/bin/ndt", line 11, in <module>
    load_entry_point(\'nameless-deploy-tools\', \'console_scripts\', \'ndt\')()
  File "/home/pasi/.pyenv/versions/3.7.2/lib/python3.7/site-packages/pkg_resources/__init__.py", line 484, in load_entry_point
    return get_distribution(dist).load_entry_point(group, name)
  File "/home/pasi/.pyenv/versions/3.7.2/lib/python3.7/site-packages/pkg_resources/__init__.py", line 2714, in load_entry_point
    return ep.load()
  File "/home/pasi/.pyenv/versions/3.7.2/lib/python3.7/site-packages/pkg_resources/__init__.py", line 2332, in load
    return self.resolve()
  File "/home/pasi/.pyenv/versions/3.7.2/lib/python3.7/site-packages/pkg_resources/__init__.py", line 2338, in resolve
    module = __import__(self.module_name, fromlist=[\'__name__\'], level=0)
ImportError: bad magic number in \'n_utils\': b\'\x03\xf3\r\n\'
```

## `ndt ecr-repo-uri`

```bash
Traceback (most recent call last):
  File "/home/pasi/.pyenv/versions/3.7.2/bin/ndt", line 11, in <module>
    load_entry_point(\'nameless-deploy-tools\', \'console_scripts\', \'ndt\')()
  File "/home/pasi/.pyenv/versions/3.7.2/lib/python3.7/site-packages/pkg_resources/__init__.py", line 484, in load_entry_point
    return get_distribution(dist).load_entry_point(group, name)
  File "/home/pasi/.pyenv/versions/3.7.2/lib/python3.7/site-packages/pkg_resources/__init__.py", line 2714, in load_entry_point
    return ep.load()
  File "/home/pasi/.pyenv/versions/3.7.2/lib/python3.7/site-packages/pkg_resources/__init__.py", line 2332, in load
    return self.resolve()
  File "/home/pasi/.pyenv/versions/3.7.2/lib/python3.7/site-packages/pkg_resources/__init__.py", line 2338, in resolve
    module = __import__(self.module_name, fromlist=[\'__name__\'], level=0)
ImportError: bad magic number in \'n_utils\': b\'\x03\xf3\r\n\'
```

## `ndt enable-profile`

```bash
Traceback (most recent call last):
  File "/home/pasi/.pyenv/versions/3.7.2/bin/ndt", line 11, in <module>
    load_entry_point(\'nameless-deploy-tools\', \'console_scripts\', \'ndt\')()
  File "/home/pasi/.pyenv/versions/3.7.2/lib/python3.7/site-packages/pkg_resources/__init__.py", line 484, in load_entry_point
    return get_distribution(dist).load_entry_point(group, name)
  File "/home/pasi/.pyenv/versions/3.7.2/lib/python3.7/site-packages/pkg_resources/__init__.py", line 2714, in load_entry_point
    return ep.load()
  File "/home/pasi/.pyenv/versions/3.7.2/lib/python3.7/site-packages/pkg_resources/__init__.py", line 2332, in load
    return self.resolve()
  File "/home/pasi/.pyenv/versions/3.7.2/lib/python3.7/site-packages/pkg_resources/__init__.py", line 2338, in resolve
    module = __import__(self.module_name, fromlist=[\'__name__\'], level=0)
ImportError: bad magic number in \'n_utils\': b\'\x03\xf3\r\n\'
```

## `ndt get-images`

```bash
Traceback (most recent call last):
  File "/home/pasi/.pyenv/versions/3.7.2/bin/ndt", line 11, in <module>
    load_entry_point(\'nameless-deploy-tools\', \'console_scripts\', \'ndt\')()
  File "/home/pasi/.pyenv/versions/3.7.2/lib/python3.7/site-packages/pkg_resources/__init__.py", line 484, in load_entry_point
    return get_distribution(dist).load_entry_point(group, name)
  File "/home/pasi/.pyenv/versions/3.7.2/lib/python3.7/site-packages/pkg_resources/__init__.py", line 2714, in load_entry_point
    return ep.load()
  File "/home/pasi/.pyenv/versions/3.7.2/lib/python3.7/site-packages/pkg_resources/__init__.py", line 2332, in load
    return self.resolve()
  File "/home/pasi/.pyenv/versions/3.7.2/lib/python3.7/site-packages/pkg_resources/__init__.py", line 2338, in resolve
    module = __import__(self.module_name, fromlist=[\'__name__\'], level=0)
ImportError: bad magic number in \'n_utils\': b\'\x03\xf3\r\n\'
```

## `ndt interpolate-file`

```bash
Traceback (most recent call last):
  File "/home/pasi/.pyenv/versions/3.7.2/bin/ndt", line 11, in <module>
    load_entry_point(\'nameless-deploy-tools\', \'console_scripts\', \'ndt\')()
  File "/home/pasi/.pyenv/versions/3.7.2/lib/python3.7/site-packages/pkg_resources/__init__.py", line 484, in load_entry_point
    return get_distribution(dist).load_entry_point(group, name)
  File "/home/pasi/.pyenv/versions/3.7.2/lib/python3.7/site-packages/pkg_resources/__init__.py", line 2714, in load_entry_point
    return ep.load()
  File "/home/pasi/.pyenv/versions/3.7.2/lib/python3.7/site-packages/pkg_resources/__init__.py", line 2332, in load
    return self.resolve()
  File "/home/pasi/.pyenv/versions/3.7.2/lib/python3.7/site-packages/pkg_resources/__init__.py", line 2338, in resolve
    module = __import__(self.module_name, fromlist=[\'__name__\'], level=0)
ImportError: bad magic number in \'n_utils\': b\'\x03\xf3\r\n\'
```

## `ndt json-to-yaml`

```bash
Traceback (most recent call last):
  File "/home/pasi/.pyenv/versions/3.7.2/bin/ndt", line 11, in <module>
    load_entry_point(\'nameless-deploy-tools\', \'console_scripts\', \'ndt\')()
  File "/home/pasi/.pyenv/versions/3.7.2/lib/python3.7/site-packages/pkg_resources/__init__.py", line 484, in load_entry_point
    return get_distribution(dist).load_entry_point(group, name)
  File "/home/pasi/.pyenv/versions/3.7.2/lib/python3.7/site-packages/pkg_resources/__init__.py", line 2714, in load_entry_point
    return ep.load()
  File "/home/pasi/.pyenv/versions/3.7.2/lib/python3.7/site-packages/pkg_resources/__init__.py", line 2332, in load
    return self.resolve()
  File "/home/pasi/.pyenv/versions/3.7.2/lib/python3.7/site-packages/pkg_resources/__init__.py", line 2338, in resolve
    module = __import__(self.module_name, fromlist=[\'__name__\'], level=0)
ImportError: bad magic number in \'n_utils\': b\'\x03\xf3\r\n\'
```

## `ndt latest-snapshot`

```bash
Traceback (most recent call last):
  File "/home/pasi/.pyenv/versions/3.7.2/bin/ndt", line 11, in <module>
    load_entry_point(\'nameless-deploy-tools\', \'console_scripts\', \'ndt\')()
  File "/home/pasi/.pyenv/versions/3.7.2/lib/python3.7/site-packages/pkg_resources/__init__.py", line 484, in load_entry_point
    return get_distribution(dist).load_entry_point(group, name)
  File "/home/pasi/.pyenv/versions/3.7.2/lib/python3.7/site-packages/pkg_resources/__init__.py", line 2714, in load_entry_point
    return ep.load()
  File "/home/pasi/.pyenv/versions/3.7.2/lib/python3.7/site-packages/pkg_resources/__init__.py", line 2332, in load
    return self.resolve()
  File "/home/pasi/.pyenv/versions/3.7.2/lib/python3.7/site-packages/pkg_resources/__init__.py", line 2338, in resolve
    module = __import__(self.module_name, fromlist=[\'__name__\'], level=0)
ImportError: bad magic number in \'n_utils\': b\'\x03\xf3\r\n\'
```

## `ndt list-components`

```bash
Traceback (most recent call last):
  File "/home/pasi/.pyenv/versions/3.7.2/bin/ndt", line 11, in <module>
    load_entry_point(\'nameless-deploy-tools\', \'console_scripts\', \'ndt\')()
  File "/home/pasi/.pyenv/versions/3.7.2/lib/python3.7/site-packages/pkg_resources/__init__.py", line 484, in load_entry_point
    return get_distribution(dist).load_entry_point(group, name)
  File "/home/pasi/.pyenv/versions/3.7.2/lib/python3.7/site-packages/pkg_resources/__init__.py", line 2714, in load_entry_point
    return ep.load()
  File "/home/pasi/.pyenv/versions/3.7.2/lib/python3.7/site-packages/pkg_resources/__init__.py", line 2332, in load
    return self.resolve()
  File "/home/pasi/.pyenv/versions/3.7.2/lib/python3.7/site-packages/pkg_resources/__init__.py", line 2338, in resolve
    module = __import__(self.module_name, fromlist=[\'__name__\'], level=0)
ImportError: bad magic number in \'n_utils\': b\'\x03\xf3\r\n\'
```

## `ndt list-file-to-json`

```bash
Traceback (most recent call last):
  File "/home/pasi/.pyenv/versions/3.7.2/bin/ndt", line 11, in <module>
    load_entry_point(\'nameless-deploy-tools\', \'console_scripts\', \'ndt\')()
  File "/home/pasi/.pyenv/versions/3.7.2/lib/python3.7/site-packages/pkg_resources/__init__.py", line 484, in load_entry_point
    return get_distribution(dist).load_entry_point(group, name)
  File "/home/pasi/.pyenv/versions/3.7.2/lib/python3.7/site-packages/pkg_resources/__init__.py", line 2714, in load_entry_point
    return ep.load()
  File "/home/pasi/.pyenv/versions/3.7.2/lib/python3.7/site-packages/pkg_resources/__init__.py", line 2332, in load
    return self.resolve()
  File "/home/pasi/.pyenv/versions/3.7.2/lib/python3.7/site-packages/pkg_resources/__init__.py", line 2338, in resolve
    module = __import__(self.module_name, fromlist=[\'__name__\'], level=0)
ImportError: bad magic number in \'n_utils\': b\'\x03\xf3\r\n\'
```

## `ndt list-jobs`

```bash
Traceback (most recent call last):
  File "/home/pasi/.pyenv/versions/3.7.2/bin/ndt", line 11, in <module>
    load_entry_point(\'nameless-deploy-tools\', \'console_scripts\', \'ndt\')()
  File "/home/pasi/.pyenv/versions/3.7.2/lib/python3.7/site-packages/pkg_resources/__init__.py", line 484, in load_entry_point
    return get_distribution(dist).load_entry_point(group, name)
  File "/home/pasi/.pyenv/versions/3.7.2/lib/python3.7/site-packages/pkg_resources/__init__.py", line 2714, in load_entry_point
    return ep.load()
  File "/home/pasi/.pyenv/versions/3.7.2/lib/python3.7/site-packages/pkg_resources/__init__.py", line 2332, in load
    return self.resolve()
  File "/home/pasi/.pyenv/versions/3.7.2/lib/python3.7/site-packages/pkg_resources/__init__.py", line 2338, in resolve
    module = __import__(self.module_name, fromlist=[\'__name__\'], level=0)
ImportError: bad magic number in \'n_utils\': b\'\x03\xf3\r\n\'
```

## `ndt load-parameters`

```bash
Traceback (most recent call last):
  File "/home/pasi/.pyenv/versions/3.7.2/bin/ndt", line 11, in <module>
    load_entry_point(\'nameless-deploy-tools\', \'console_scripts\', \'ndt\')()
  File "/home/pasi/.pyenv/versions/3.7.2/lib/python3.7/site-packages/pkg_resources/__init__.py", line 484, in load_entry_point
    return get_distribution(dist).load_entry_point(group, name)
  File "/home/pasi/.pyenv/versions/3.7.2/lib/python3.7/site-packages/pkg_resources/__init__.py", line 2714, in load_entry_point
    return ep.load()
  File "/home/pasi/.pyenv/versions/3.7.2/lib/python3.7/site-packages/pkg_resources/__init__.py", line 2332, in load
    return self.resolve()
  File "/home/pasi/.pyenv/versions/3.7.2/lib/python3.7/site-packages/pkg_resources/__init__.py", line 2338, in resolve
    module = __import__(self.module_name, fromlist=[\'__name__\'], level=0)
ImportError: bad magic number in \'n_utils\': b\'\x03\xf3\r\n\'
```

## `ndt logs`

```bash
